Workbook

Sheet Dashboard
A1: FPL 2026/27 Model — v0.2 Full Player Universe
A3: Snapshot | B3: 18 Aug 2026 | D3: Position | E3: Players | F3: Avg Price (£m) | G3: Avg Hist Mins
A4: Players | B4: 567 | D4: GK | E4: =COUNTIF(Players!$E$2:$E$568,D4) -> 63 | F4: =AVERAGEIF(Players!$E$2:$E$568,D4,Players!$G$2:$G$568) -> 4.531746 | G4: =AVERAGEIF(Players!$E$2:$E$568,D4,Players!$H$2:$H$568) -> 951.85714
A5: Teams | B5: 20 | D5: DEF | E5: =COUNTIF(Players!$E$2:$E$568,D5) -> 186 | F5: =AVERAGEIF(Players!$E$2:$E$568,D5,Players!$G$2:$G$568) -> 4.7043011 | G5: =AVERAGEIF(Players!$E$2:$E$568,D5,Players!$H$2:$H$568) -> 1196.9247
A6: Fixtures | B6: 380 | D6: MID | E6: =COUNTIF(Players!$E$2:$E$568,D6) -> 250 | F6: =AVERAGEIF(Players!$E$2:$E$568,D6,Players!$G$2:$G$568) -> 5.546 | G6: =AVERAGEIF(Players!$E$2:$E$568,D6,Players!$H$2:$H$568) -> 1054.728
A7: Player source | B7: FPL API snapshot via vaastav | D7: FWD | E7: =COUNTIF(Players!$E$2:$E$568,D7) -> 68 | F7: =AVERAGEIF(Players!$E$2:$E$568,D7,Players!$G$2:$G$568) -> 5.8088235 | G7: =AVERAGEIF(Players!$E$2:$E$568,D7,Players!$H$2:$H$568) -> 824.57353
A8: Stage | B8: Universe + historical priors
A10: Next modelling step: current expected minutes + bookmaker-implied fixture xG/clean-sheet probabilities.

Sheet Players
A1: Player ID | B1: Player | C1: Full Name | D1: Team | E1: Position | F1: Start Price (£m) | G1: Current Price (£m) | H1: Mins 25/26 | I1: xG 25/26 | J1: xA 25/26 | K1: xG90 Hist | L1: xA90 Hist | M1: Goals 25/26 | N1: Assists 25/26 | O1: FPL Pts 25/26 | P1: Pts/Game | Q1: Starts 25/26 | R1: DC90 | S1: Pens Order | T1: Direct FK Order | U1: Corners/IFK Order | V1: New Club? | W1: New Manager? | X1: Role Change | Y1: Start Prob | Z1: Exp Mins | AA1: Sample Weight | AB1: Pos xG90 Prior | AC1: Pos xA90 Prior | AD1: xG90 Prior | AE1: xA90 Prior | AF1: League Adj | AG1: Role Adj | AH1: Team Adj | AI1: Adj xG90 | AJ1: Adj xA90 | AK1: Status | AL1: Chance Play GW1 | AM1: News | AN1: Ownership % | AO1: Selectable? | AP1: Team Join Date | AQ1: Test Sample? | AR1: Notes | AS1: Source URL
A2: 1 | B2: Raya | C2: David Raya Martín | D2: Arsenal | E2: GK | F2: 6 | G2: 6 | H2: 3330 | I2: 0 | J2: 0.07 | K2: =IFERROR(I2*90/H2,0) -> 0 | L2: =IFERROR(J2*90/H2,0) -> 0.0018918919 | M2: 0 | N2: 0 | O2: 162 | P2: 4.4 | Q2: 37 | R2: 0 | V2: FALSE | W2: =IFERROR(VLOOKUP(D2,Teams!$B$2:$I$21,6,FALSE),"") -> 0 | X2: None | AA2: =IFERROR(H2/(H2+Priors!$G$3),0) -> 0.76905312 | AB2: =VLOOKUP(E2,Priors!$A$3:$C$6,2,FALSE) -> 0.00024013207 | AC2: =VLOOKUP(E2,Priors!$A$3:$C$6,3,FALSE) -> 0.0019810896 | AD2: =AA2*K2+(1-AA2)*AB2 -> 5.5457753e-05 | AE2: =AA2*L2+(1-AA2)*AC2 -> 0.0019124918 | AF2: 1 | AG2: 1 | AH2: =IFERROR(VLOOKUP(D2,Teams!$B$2:$I$21,7,FALSE),1) -> 1 | AI2: =AD2*AF2*AG2*AH2 -> 5.5457753e-05 | AJ2: =AE2*AF2*AG2*AH2 -> 0.0019124918 | AK2: Available | AN2: 0.307 | AO2: TRUE | AP2: 2024-07-04 | AQ2: TRUE | AS2: https://raw.githubusercontent.com/vaastav/Fantasy-Premier-League/master/data/2026-27/players_raw.csv
A3: 2 | B3: Arrizabalaga | C3: Kepa Arrizabalaga Revuelta | D3: Arsenal | E3: GK | F3: 5 | G3: 5 | H3: 90 | I3: 0 | J3: 0 | K3: =IFERROR(I3*90/H3,0) -> 0 | L3: =IFERROR(J3*90/H3,0) -> 0 | M3: 0 | N3: 0 | O3: 2 | P3: 2 | Q3: 1 | R3: 0 | V3: FALSE | W3: =IFERROR(VLOOKUP(D3,Teams!$B$2:$I$21,6,FALSE),"") -> 0 | X3: None | AA3: =IFERROR(H3/(H3+Priors!$G$3),0) -> 0.082568807 | AB3: =VLOOKUP(E3,Priors!$A$3:$C$6,2,FALSE) -> 0.00024013207 | AC3: =VLOOKUP(E3,Priors!$A$3:$C$6,3,FALSE) -> 0.0019810896 | AD3: =AA3*K3+(1-AA3)*AB3 -> 0.00022030465 | AE3: =AA3*L3+(1-AA3)*AC3 -> 0.0018175134 | AF3: 1 | AG3: 1 | AH3: =IFERROR(VLOOKUP(D3,Teams!$B$2:$I$21,7,FALSE),1) -> 1 | AI3: =AD3*AF3*AG3*AH3 -> 0.00022030465 | AJ3: =AE3*AF3*AG3*AH3 -> 0.0018175134 | AK3: Available | AN3: 0.002 | AO3: TRUE | AP3: 2025-07-01 | AQ3: FALSE | AS3: https://raw.githubusercontent.com/vaastav/Fantasy-Premier-League/master/data/2026-27/players_raw.csv
A4: 3 | B4: Meslier | C4: Illan Meslier | D4: Arsenal | E4: GK | F4: 5 | G4: 5 | H4: 0 | I4: 0 | J4: 0 | K4: =IFERROR(I4*90/H4,0) -> 0 | L4: =IFERROR(J4*90/H4,0) -> 0 | M4: 11 | N4: 0 | O4: 0 | P4: 0 | Q4: 0 | R4: 0 | V4: TRUE | W4: =IFERROR(VLOOKUP(D4,Teams!$B$2:$I$21,6,FALSE),"") -> 0 | X4: None | AA4: =IFERROR(H4/(H4+Priors!$G$3),0) -> 0 | AB4: =VLOOKUP(E4,Priors!$A$3:$C$6,2,FALSE) -> 0.00024013207 | AC4: =VLOOKUP(E4,Priors!$A$3:$C$6,3,FALSE) -> 0.0019810896 | AD4: =AA4*K4+(1-AA4)*AB4 -> 0.00024013207 | AE4: =AA4*L4+(1-AA4)*AC4 -> 0.0019810896 | AF4: 1 | AG4: 1 | AH4: =IFERROR(VLOOKUP(D4,Teams!$B$2:$I$21,7,FALSE),1) -> 1 | AI4: =AD4*AF4*AG4*AH4 -> 0.00024013207 | AJ4: =AE4*AF4*AG4*AH4 -> 0.0019810896 | AK4: Available | AN4: 0.001 | AO4: TRUE | AP4: 2026-07-09 | AQ4: FALSE | AS4: https://raw.githubusercontent.com/vaastav/Fantasy-Premier-League/master/data/2026-27/players_raw.csv
A5: 4 | B5: Gabriel | C5: Gabriel Magalhães | D5: Arsenal | E5: DEF | F5: 8 | G5: 8 | H5: 2750 | I5: 2.94 | J5: 1.75 | K5: =IFERROR(I5*90/H5,0) -> 0.096218182 | L5: =IFERROR(J5*90/H5,0) -> 0.057272727 | M5: 3 | N5: 5 | O5: 209 | P5: 6.5 | Q5: 30 | R5: 9.07 | V5: FALSE | W5: =IFERROR(VLOOKUP(D5,Teams!$B$2:$I$21,6,FALSE),"") -> 0 | X5: None | AA5: =IFERROR(H5/(H5+Priors!$G$3),0) -> 0.73333333 | AB5: =VLOOKUP(E5,Priors!$A$3:$C$6,2,FALSE) -> 0.060081391 | AC5: =VLOOKUP(E5,Priors!$A$3:$C$6,3,FALSE) -> 0.059588192 | AD5: =AA5*K5+(1-AA5)*AB5 -> 0.086581704 | AE5: =AA5*L5+(1-AA5)*AC5 -> 0.057890185 | AF5: 1 | AG5: 1 | AH5: =IFERROR(VLOOKUP(D5,Teams!$B$2:$I$21,7,FALSE),1) -> 1 | AI5: =AD5*AF5*AG5*AH5 -> 0.086581704 | AJ5: =AE5*AF5*AG5*AH5 -> 0.057890185 | AK5: Available | AN5: 0.259 | AO5: TRUE | AP5: 2020-09-01 | AQ5: TRUE | AS5: https://raw.githubusercontent.com/vaastav/Fantasy-Premier-League/master/data/2026-27/players_raw.csv
A6: 5 | B6: J.Timber | C6: Jurriën Timber | D6: Arsenal | E6: DEF | F6: 6.5 | G6: 6.5 | H6: 2452 | I6: 4.71 | J6: 1.53 | K6: =IFERROR(I6*90/H6,0) -> 0.17287928 | L6: =IFERROR(J6*90/H6,0) -> 0.056158238 | M6: 3 | N6: 6 | O6: 149 | P6: 5 | Q6: 28 | R6: 5.43 | V6: FALSE | W6: =IFERROR(VLOOKUP(D6,Teams!$B$2:$I$21,6,FALSE),"") -> 0 | X6: None | AA6: =IFERROR(H6/(H6+Priors!$G$3),0) -> 0.71031286 | AB6: =VLOOKUP(E6,Priors!$A$3:$C$6,2,FALSE) -> 0.060081391 | AC6: =VLOOKUP(E6,Priors!$A$3:$C$6,3,FALSE) -> 0.059588192 | AD6: =AA6*K6+(1-AA6)*AB6 -> 0.14020318 | AE6: =AA6*L6+(1-AA6)*AC6 -> 0.057151852 | AF6: 1 | AG6: 1 | AH6: =IFERROR(VLOOKUP(D6,Teams!$B$2:$I$21,7,FALSE),1) -> 1 | AI6: =AD6*AF6*AG6*AH6 -> 0.14020318 | AJ6: =AE6*AF6*AG6*AH6 -> 0.057151852 | AK6: Injured | AL6: 0 | AM6: Groin injury - Expected back 21 Aug | AN6: 0.005 | AO6: TRUE | AP6: 2023-07-14 | AQ6: FALSE | AS6: https://raw.githubusercontent.com/vaastav/Fantasy-Premier-League/master/data/2026-27/players_raw.csv
A7: 6 | B7: Saliba | C7: William Saliba | D7: Arsenal | E7: DEF | F7: 6 | G7: 6 | H7: 2614 | I7: 0.88 | J7: 1.21 | K7: =IFERROR(I7*90/H7,0) -> 0.030298393 | L7: =IFERROR(J7*90/H7,0) -> 0.041660291 | M7: 1 | N7: 0 | O7: 137 | P7: 4.4 | Q7: 30 | R7: 6.64 | V7: FALSE | W7: =IFERROR(VLOOKUP(D7,Teams!$B$2:$I$21,6,FALSE),"") -> 0 | X7: None | AA7: =IFERROR(H7/(H7+Priors!$G$3),0) -> 0.72329828 | AB7: =VLOOKUP(E7,Priors!$A$3:$C$6,2,FALSE) -> 0.060081391 | AC7: =VLOOKUP(E7,Priors!$A$3:$C$6,3,FALSE) -> 0.059588192 | AD7: =AA7*K7+(1-AA7)*AB7 -> 0.0385394 | AE7: =AA7*L7+(1-AA7)*AC7 -> 0.046620972 | AF7: 1 | AG7: 1 | AH7: =IFERROR(VLOOKUP(D7,Teams!$B$2:$I$21,7,FALSE),1) -> 1 | AI7: =AD7*AF7*AG7*AH7 -> 0.0385394 | AJ7: =AE7*AF7*AG7*AH7 -> 0.046620972 | AK7: Injured | AL7: 0 | AM7: Back injury - Unknown return date | AN7: 0.005 | AO7: TRUE | AP7: 2019-07-25 | AQ7: FALSE | AS7: https://raw.githubusercontent.com/vaastav/Fantasy-Premier-League/master/data/2026-27/players_raw.csv
A8: 7 | B8: Lewis-Skelly | C8: Myles Lewis-Skelly | D8: Arsenal | E8: MID | F8: 5.5 | G8: 5.5 | H8: 697 | I8: 0.1 | J8: 0.2 | K8: =IFERROR(I8*90/H8,0) -> 0.012912482 | L8: =IFERROR(J8*90/H8,0) -> 0.025824964 | M8: 0 | N8: 0 | O8: 29 | P8: 1.4 | Q8: 5 | R8: 3.23 | V8: FALSE | W8: =IFERROR(VLOOKUP(D8,Teams!$B$2:$I$21,6,FALSE),"") -> 0 | X8: None | AA8: =IFERROR(H8/(H8+Priors!$G$3),0) -> 0.41072481 | AB8: =VLOOKUP(E8,Priors!$A$3:$C$6,2,FALSE) -> 0.15714383 | AC8: =VLOOKUP(E8,Priors!$A$3:$C$6,3,FALSE) -> 0.13222063 | AD8: =AA8*K8+(1-AA8)*AB8 -> 0.097904439 | AE8: =AA8*L8+(1-AA8)*AC8 -> 0.08852129 | AF8: 1 | AG8: 1 | AH8: =IFERROR(VLOOKUP(D8,Teams!$B$2:$I$21,7,FALSE),1) -> 1 | AI8: =AD8*AF8*AG8*AH8 -> 0.097904439 | AJ8: =AE8*AF8*AG8*AH8 -> 0.08852129 | AK8: Available | AN8: 0.003 | AO8: TRUE | AP8: 2022-12-04 | AQ8: FALSE | AS8: https://raw.githubusercontent.com/vaastav/Fantasy-Premier-League/master/data/2026-27/players_raw.csv
A9: 8 | B9: Calafiori | C9: Riccardo Calafiori | D9: Arsenal | E9: DEF | F9: 5.5 | G9: 5.5 | H9: 1697 | I9: 3.36 | J9: 0.76 | K9: =IFERROR(I9*90/H9,0) -> 0.17819682 | L9: =IFERROR(J9*90/H9,0) -> 0.040306423 | M9: 1 | N9: 2 | O9: 109 | P9: 4.2 | Q9: 22 | R9: 5.41 | V9: FALSE | W9: =IFERROR(VLOOKUP(D9,Teams!$B$2:$I$21,6,FALSE),"") -> 0 | X9: None | AA9: =IFERROR(H9/(H9+Priors!$G$3),0) -> 0.62921765 | AB9: =VLOOKUP(E9,Priors!$A$3:$C$6,2,FALSE) -> 0.060081391 | AC9: =VLOOKUP(E9,Priors!$A$3:$C$6,3,FALSE) -> 0.059588192 | AD9: =AA9*K9+(1-AA9)*AB9 -> 0.1344017 | AE9: =AA9*L9+(1-AA9)*AC9 -> 0.047455763 | AF9: 1 | AG9: 1 | AH9: =IFERROR(VLOOKUP(D9,Teams!$B$2:$I$21,7,FALSE),1) -> 1 | AI9: =AD9*AF9*AG9*AH9 -> 0.1344017 | AJ9: =AE9*AF9*AG9*AH9 -> 0.047455763 | AK9: Available | AN9: 0.153 | AO9: TRUE | AP9: 2024-07-29 | AQ9: FALSE | AS9: https://raw.githubusercontent.com/vaastav/Fantasy-Premier-League/master/data/2026-27/players_raw.csv
A10: 9 | B10: Hincapie | C10: Piero Hincapié | D10: Arsenal | E10: DEF | F10: 5.5 | G10: 5.5 | H10: 1787 | I10: 0.36 | J10: 1.67 | K10: =IFERROR(I10*90/H10,0) -> 0.018130946 | L10: =IFERROR(J10*90/H10,0) -> 0.084107443 | M10: 1 | N10: 2 | O10: 87 | P10: 3.5 | Q10: 20 | R10: 8.61 | V10: TRUE | W10: =IFERROR(VLOOKUP(D10,Teams!$B$2:$I$21,6,FALSE),"") -> 0 | X10: None | AA10: =IFERROR(H10/(H10+Priors!$G$3),0) -> 0.64119125 | AB10: =VLOOKUP(E10,Priors!$A$3:$C$6,2,FALSE) -> 0.060081391 | AC10: =VLOOKUP(E10,Priors!$A$3:$C$6,3,FALSE) -> 0.059588192 | AD10: =AA10*K10+(1-AA10)*AB10 -> 0.033183133 | AE10: =AA10*L10+(1-AA10)*AC10 -> 0.075309721 | AF10: 1 | AG10: 1 | AH10: =IFERROR(VLOOKUP(D10,Teams!$B$2:$I$21,7,FALSE),1) -> 1 | AI10: =AD10*AF10*AG10*AH10 -> 0.033183133 | AJ10: =AE10*AF10*AG10*AH10 -> 0.075309721 | AK10: Available | AN10: 0.044 | AO10: TRUE | AP10: 2026-07-01 | AQ10: FALSE | AS10: https://raw.githubusercontent.com/vaastav/Fantasy-Premier-League/master/data/2026-27/players_raw.csv
A11: 10 | B11: White | C11: Benjamin White | D11: Arsenal | E11: DEF | F11: 5.5 | G11: 5.5 | H11: 699 | I11: 0.45 | J11: 0.69 | K11: =IFERROR(I11*90/H11,0) -> 0.057939914 | L11: =IFERROR(J11*90/H11,0) -> 0.088841202 | M11: 0 | N11: 1 | O11: 45 | P11: 3.8 | Q11: 9 | R11: 6.82 | V11: FALSE | W11: =IFERROR(VLOOKUP(D11,Teams!$B$2:$I$21,6,FALSE),"") -> 0 | X11: None | AA11: =IFERROR(H11/(H11+Priors!$G$3),0) -> 0.41141848 | AB11: =VLOOKUP(E11,Priors!$A$3:$C$6,2,FALSE) -> 0.060081391 | AC11: =VLOOKUP(E11,Priors!$A$3:$C$6,3,FALSE) -> 0.059588192 | AD11: =AA11*K11+(1-AA11)*AB11 -> 0.059200348 | AE11: =AA11*L11+(1-AA11)*AC11 -> 0.071623421 | AF11: 1 | AG11: 1 | AH11: =IFERROR(VLOOKUP(D11,Teams!$B$2:$I$21,7,FALSE),1) -> 1 | AI11: =AD11*AF11*AG11*AH11 -> 0.059200348 | AJ11: =AE11*AF11*AG11*AH11 -> 0.071623421 | AK11: Available | AL11: 100 | AN11: 0.002 | AO11: TRUE | AP11: 2021-07-30 | AQ11: FALSE | AS11: https://raw.githubusercontent.com/vaastav/Fantasy-Premier-League/master/data/2026-27/players_raw.csv
A12: 11 | B12: Mosquera | C12: Cristhian Mosquera | D12: Arsenal | E12: DEF | F12: 5.5 | G12: 5.5 | H12: 986 | I12: 0.1 | J12: 0.63 | K12: =IFERROR(I12*90/H12,0) -> 0.009127789 | L12: =IFERROR(J12*90/H12,0) -> 0.057505071 | M12: 0 | N12: 0 | O12: 40 | P12: 2 | Q12: 9 | R12: 8.67 | V12: FALSE | W12: =IFERROR(VLOOKUP(D12,Teams!$B$2:$I$21,6,FALSE),"") -> 0 | X12: None | AA12: =IFERROR(H12/(H12+Priors!$G$3),0) -> 0.49647533 | AB12: =VLOOKUP(E12,Priors!$A$3:$C$6,2,FALSE) -> 0.060081391 | AC12: =VLOOKUP(E12,Priors!$A$3:$C$6,3,FALSE) -> 0.059588192 | AD12: =AA12*K12+(1-AA12)*AB12 -> 0.034784185 | AE12: =AA12*L12+(1-AA12)*AC12 -> 0.058553974 | AF12: 1 | AG12: 1 | AH12: =IFERROR(VLOOKUP(D12,Teams!$B$2:$I$21,7,FALSE),1) -> 1 | AI12: =AD12*AF12*AG12*AH12 -> 0.034784185 | AJ12: =AE12*AF12*AG12*AH12 -> 0.058553974 | AK12: Available | AN12: 0.169 | AO12: TRUE | AP12: 2025-07-24 | AQ12: FALSE | AS12: https://raw.githubusercontent.com/vaastav/Fantasy-Premier-League/master/data/2026-27/players_raw.csv
A13: 12 | B13: Saka | C13: Bukayo Saka | D13: Arsenal | E13: MID | F13: 9.5 | G13: 9.5 | H13: 2218 | I13: 7.57 | J13: 7.16 | K13: =IFERROR(I13*90/H13,0) -> 0.30716862 | L13: =IFERROR(J13*90/H13,0) -> 0.29053201 | M13: 7 | N13: 10 | O13: 157 | P13: 5.1 | Q13: 25 | R13: 7.47 | S13: 1 | T13: 2 | U13: 6 | V13: FALSE | W13: =IFERROR(VLOOKUP(D13,Teams!$B$2:$I$21,6,FALSE),"") -> 0 | X13: None | AA13: =IFERROR(H13/(H13+Priors!$G$3),0) -> 0.68924798 | AB13: =VLOOKUP(E13,Priors!$A$3:$C$6,2,FALSE) -> 0.15714383 | AC13: =VLOOKUP(E13,Priors!$A$3:$C$6,3,FALSE) -> 0.13222063 | AD13: =AA13*K13+(1-AA13)*AB13 -> 0.26054811 | AE13: =AA13*L13+(1-AA13)*AC13 -> 0.24133643 | AF13: 1 | AG13: 1 | AH13: =IFERROR(VLOOKUP(D13,Teams!$B$2:$I$21,7,FALSE),1) -> 1 | AI13: =AD13*AF13*AG13*AH13 -> 0.26054811 | AJ13: =AE13*AF13*AG13*AH13 -> 0.24133643 | AK13: Available | AN13: 0.106 | AO13: TRUE | AP13: 2018-11-28 | AQ13: FALSE | AS13: https://raw.githubusercontent.com/vaastav/Fantasy-Premier-League/master/data/2026-27/players_raw.csv
A14: 13 | B14: Rice | C14: Declan Rice | D14: Arsenal | E14: MID | F14: 7.5 | G14: 7.5 | H14: 3093 | I14: 3.15 | J14: 7.32 | K14: =IFERROR(I14*90/H14,0) -> 0.091658584 | L14: =IFERROR(J14*90/H14,0) -> 0.21299709 | M14: 4 | N14: 9 | O14: 184 | P14: 5.1 | Q14: 35 | R14: 10.94 | T14: 1 | U14: 5 | V14: FALSE | W14: =IFERROR(VLOOKUP(D14,Teams!$B$2:$I$21,6,FALSE),"") -> 0 | X14: None | AA14: =IFERROR(H14/(H14+Priors!$G$3),0) -> 0.75568043 | AB14: =VLOOKUP(E14,Priors!$A$3:$C$6,2,FALSE) -> 0.15714383 | AC14: =VLOOKUP(E14,Priors!$A$3:$C$6,3,FALSE) -> 0.13222063 | AD14: =AA14*K14+(1-AA14)*AB14 -> 0.10765791 | AE14: =AA14*L14+(1-AA14)*AC14 -> 0.19326182 | AF14: 1 | AG14: 1 | AH14: =IFERROR(VLOOKUP(D14,Teams!$B$2:$I$21,7,FALSE),1) -> 1 | AI14: =AD14*AF14*AG14*AH14 -> 0.10765791 | AJ14: =AE14*AF14*AG14*AH14 -> 0.19326182 | AK14: Available | AN14: 0.223 | AO14: TRUE | AP14: 2023-07-15 | AQ14: FALSE | AS14: https://raw.githubusercontent.com/vaastav/Fantasy-Premier-League/master/data/2026-27/players_raw.csv
A15: 14 | B15: Eze | C15: Eberechi Eze | D15: Arsenal | E15: MID | F15: 6.5 | G15: 6.5 | H15: 1885 | I15: 5.18 | J15: 2.66 | K15: =IFERROR(I15*90/H15,0) -> 0.24732095 | L15: =IFERROR(J15*90/H15,0) -> 0.12700265 | M15: 7 | N15: 3 | O15: 113 | P15: 3.4 | Q15: 22 | R15: 5.73 | T15: 3 | V15: FALSE | W15: =IFERROR(VLOOKUP(D15,Teams!$B$2:$I$21,6,FALSE),"") -> 0 | X15: None | AA15: =IFERROR(H15/(H15+Priors!$G$3),0) -> 0.65337955 | AB15: =VLOOKUP(E15,Priors!$A$3:$C$6,2,FALSE) -> 0.15714383 | AC15: =VLOOKUP(E15,Priors!$A$3:$C$6,3,FALSE) -> 0.13222063 | AD15: =AA15*K15+(1-AA15)*AB15 -> 0.21606372 | AE15: =AA15*L15+(1-AA15)*AC15 -> 0.12881131 | AF15: 1 | AG15: 1 | AH15: =IFERROR(VLOOKUP(D15,Teams!$B$2:$I$21,7,FALSE),1) -> 1 | AI15: =AD15*AF15*AG15*AH15 -> 0.21606372 | AJ15: =AE15*AF15*AG15*AH15 -> 0.12881131 | AK15: Available | AN15: 0.033 | AO15: TRUE | AP15: 2025-08-23 | AQ15: FALSE | AS15: https://raw.githubusercontent.com/vaastav/Fantasy-Premier-League/master/data/2026-27/players_raw.csv
A16: 15 | B16: Ødegaard | C16: Martin Ødegaard | D16: Arsenal | E16: MID | F16: 6.5 | G16: 6.5 | H16: 1363 | I16: 1.25 | J16: 3.65 | K16: =IFERROR(I16*90/H16,0) -> 0.082538518 | L16: =IFERROR(J16*90/H16,0) -> 0.24101247 | M16: 1 | N16: 7 | O16: 74 | P16: 3.1 | Q16: 16 | R16: 6.74 | S16: 3 | U16: 8 | V16: FALSE | W16: =IFERROR(VLOOKUP(D16,Teams!$B$2:$I$21,6,FALSE),"") -> 0 | X16: None | AA16: =IFERROR(H16/(H16+Priors!$G$3),0) -> 0.57680914 | AB16: =VLOOKUP(E16,Priors!$A$3:$C$6,2,FALSE) -> 0.15714383 | AC16: =VLOOKUP(E16,Priors!$A$3:$C$6,3,FALSE) -> 0.13222063 | AD16: =AA16*K16+(1-AA16)*AB16 -> 0.11411081 | AE16: =AA16*L16+(1-AA16)*AC16 -> 0.19497276 | AF16: 1 | AG16: 1 | AH16: =IFERROR(VLOOKUP(D16,Teams!$B$2:$I$21,7,FALSE),1) -> 1 | AI16: =AD16*AF16*AG16*AH16 -> 0.11411081 | AJ16: =AE16*AF16*AG16*AH16 -> 0.19497276 | AK16: Available | AN16: 0.03 | AO16: TRUE | AP16: 2021-08-20 | AQ16: FALSE | AS16: https://raw.githubusercontent.com/vaastav/Fantasy-Premier-League/master/data/2026-27/players_raw.csv
A17: 16 | B17: Madueke | C17: Noni Madueke | D17: Arsenal | E17: MID | F17: 6.5 | G17: 6.5 | H17: 1205 | I17: 1.23 | J17: 2.86 | K17: =IFERROR(I17*90/H17,0) -> 0.09186722 | L17: =IFERROR(J17*90/H17,0) -> 0.21360996 | M17: 3 | N17: 1 | O17: 72 | P17: 2.8 | Q17: 16 | R17: 5.23 | U17: 7 | V17: FALSE | W17: =IFERROR(VLOOKUP(D17,Teams!$B$2:$I$21,6,FALSE),"") -> 0 | X17: None | AA17: =IFERROR(H17/(H17+Priors!$G$3),0) -> 0.54648526 | AB17: =VLOOKUP(E17,Priors!$A$3:$C$6,2,FALSE) -> 0.15714383 | AC17: =VLOOKUP(E17,Priors!$A$3:$C$6,3,FALSE) -> 0.13222063 | AD17: =AA17*K17+(1-AA17)*AB17 -> 0.12147113 | AE17: =AA17*L17+(1-AA17)*AC17 -> 0.1766987 | AF17: 1 | AG17: 1 | AH17: =IFERROR(VLOOKUP(D17,Teams!$B$2:$I$21,7,FALSE),1) -> 1 | AI17: =AD17*AF17*AG17*AH17 -> 0.12147113 | AJ17: =AE17*AF17*AG17*AH17 -> 0.1766987 | AK17: Available | AN17: 0.004 | AO17: TRUE | AP17: 2025-07-18 | AQ17: FALSE | AS17: https://raw.githubusercontent.com/vaastav/Fantasy-Premier-League/master/data/2026-27/players_raw.csv
A18: 17 | B18: Merino | C18: Mikel Merino Zazón | D18: Arsenal | E18: MID | F18: 6 | G18: 6 | H18: 1024 | I18: 3.36 | J18: 1.45 | K18: =IFERROR(I18*90/H18,0) -> 0.2953125 | L18: =IFERROR(J18*90/H18,0) -> 0.12744141 | M18: 4 | N18: 3 | O18: 67 | P18: 3 | Q18: 10 | R18: 9.93 | V18: FALSE | W18: =IFERROR(VLOOKUP(D18,Teams!$B$2:$I$21,6,FALSE),"") -> 0 | X18: None | AA18: =IFERROR(H18/(H18+Priors!$G$3),0) -> 0.50592885 | AB18: =VLOOKUP(E18,Priors!$A$3:$C$6,2,FALSE) -> 0.15714383 | AC18: =VLOOKUP(E18,Priors!$A$3:$C$6,3,FALSE) -> 0.13222063 | AD18: =AA18*K18+(1-AA18)*AB18 -> 0.22704735 | AE18: =AA18*L18+(1-AA18)*AC18 -> 0.12980268 | AF18: 1 | AG18: 1 | AH18: =IFERROR(VLOOKUP(D18,Teams!$B$2:$I$21,7,FALSE),1) -> 1 | AI18: =AD18*AF18*AG18*AH18 -> 0.22704735 | AJ18: =AE18*AF18*AG18*AH18 -> 0.12980268 | AK18: Available | AN18: 0.012 | AO18: TRUE | AP18: 2024-08-27 | AQ18: FALSE | AS18: https://raw.githubusercontent.com/vaastav/Fantasy-Premier-League/master/data/2026-27/players_raw.csv
A19: 18 | B19: Martinelli | C19: Gabriel Martinelli | D19: Arsenal | E19: MID | F19: 6.5 | G19: 6.5 | H19: 1065 | I19: 4.12 | J19: 1.27 | K19: =IFERROR(I19*90/H19,0) -> 0.34816901 | L19: =IFERROR(J19*90/H19,0) -> 0.10732394 | M19: 1 | N19: 5 | O19: 57 | P19: 1.9 | Q19: 11 | R19: 6.51 | V19: FALSE | W19: =IFERROR(VLOOKUP(D19,Teams!$B$2:$I$21,6,FALSE),"") -> 0 | X19: None | AA19: =IFERROR(H19/(H19+Priors!$G$3),0) -> 0.5157385 | AB19: =VLOOKUP(E19,Priors!$A$3:$C$6,2,FALSE) -> 0.15714383 | AC19: =VLOOKUP(E19,Priors!$A$3:$C$6,3,FALSE) -> 0.13222063 | AD19: =AA19*K19+(1-AA19)*AB19 -> 0.25566287 | AE19: =AA19*L19+(1-AA19)*AC19 -> 0.11938045 | AF19: 1 | AG19: 1 | AH19: =IFERROR(VLOOKUP(D19,Teams!$B$2:$I$21,7,FALSE),1) -> 1 | AI19: =AD19*AF19*AG19*AH19 -> 0.25566287 | AJ19: =AE19*AF19*AG19*AH19 -> 0.11938045 | AK19: Available | AN19: 0.003 | AO19: TRUE | AP19: 2019-07-15 | AQ19: FALSE | AS19: https://raw.githubusercontent.com/vaastav/Fantasy-Premier-League/master/data/2026-27/players_raw.csv
A20: 19 | B20: Zubimendi | C20: Martín Zubimendi Ibáñez | D20: Arsenal | E20: MID | F20: 5.5 | G20: 5.5 | H20: 2991 | I20: 2.84 | J20: 2.27 | K20: =IFERROR(I20*90/H20,0) -> 0.085456369 | L20: =IFERROR(J20*90/H20,0) -> 0.068304915 | M20: 5 | N20: 1 | O20: 133 | P20: 3.5 | Q20: 34 | R20: 9.24 | V20: FALSE | W20: =IFERROR(VLOOKUP(D20,Teams!$B$2:$I$21,6,FALSE),"") -> 0 | X20: None | AA20: =IFERROR(H20/(H20+Priors!$G$3),0) -> 0.74943623 | AB20: =VLOOKUP(E20,Priors!$A$3:$C$6,2,FALSE) -> 0.15714383 | AC20: =VLOOKUP(E20,Priors!$A$3:$C$6,3,FALSE) -> 0.13222063 | AD20: =AA20*K20+(1-AA20)*AB20 -> 0.10341865 | AE20: =AA20*L20+(1-AA20)*AC20 -> 0.084319877 | AF20: 1 | AG20: 1 | AH20: =IFERROR(VLOOKUP(D20,Teams!$B$2:$I$21,7,FALSE),1) -> 1 | AI20: =AD20*AF20*AG20*AH20 -> 0.10341865 | AJ20: =AE20*AF20*AG20*AH20 -> 0.084319877 | AK20: Available | AN20: 0.015 | AO20: TRUE | AP20: 2025-07-06 | AQ20: FALSE | AS20: https://raw.githubusercontent.com/vaastav/Fantasy-Premier-League/master/data/2026-27/players_raw.csv
A21: 20 | B21: Dowman | C21: Max Dowman | D21: Arsenal | E21: MID | F21: 5.5 | G21: 5.5 | H21: 152 | I21: 1.19 | J21: 0.3 | K21: =IFERROR(I21*90/H21,0) -> 0.70460526 | L21: =IFERROR(J21*90/H21,0) -> 0.17763158 | M21: 1 | N21: 1 | O21: 16 | P21: 2.7 | Q21: 1 | R21: 9.47 | V21: TRUE | W21: =IFERROR(VLOOKUP(D21,Teams!$B$2:$I$21,6,FALSE),"") -> 0 | X21: None | AA21: =IFERROR(H21/(H21+Priors!$G$3),0) -> 0.13194444 | AB21: =VLOOKUP(E21,Priors!$A$3:$C$6,2,FALSE) -> 0.15714383 | AC21: =VLOOKUP(E21,Priors!$A$3:$C$6,3,FALSE) -> 0.13222063 | AD21: =AA21*K21+(1-AA21)*AB21 -> 0.22937833 | AE21: =AA21*L21+(1-AA21)*AC21 -> 0.13821235 | AF21: 1 | AG21: 1 | AH21: =IFERROR(VLOOKUP(D21,Teams!$B$2:$I$21,7,FALSE),1) -> 1 | AI21: =AD21*AF21*AG21*AH21 -> 0.22937833 | AJ21: =AE21*AF21*AG21*AH21 -> 0.13821235 | AK21: Available | AN21: 0.002 | AO21: TRUE | AP21: None | AQ21: FALSE | AS21: https://raw.githubusercontent.com/vaastav/Fantasy-Premier-League/master/data/2026-27/players_raw.csv
A22: 21 | B22: Nørgaard | C22: Christian Nørgaard | D22: Arsenal | E22: MID | F22: 5 | G22: 5 | H22: 101 | I22: 0.08 | J22: 0.04 | K22: =IFERROR(I22*90/H22,0) -> 0.071287129 | L22: =IFERROR(J22*90/H22,0) -> 0.035643564 | M22: 0 | N22: 0 | O22: 7 | P22: 1 | Q22: 1 | R22: 14.26 | V22: FALSE | W22: =IFERROR(VLOOKUP(D22,Teams!$B$2:$I$21,6,FALSE),"") -> 0 | X22: None | AA22: =IFERROR(H22/(H22+Priors!$G$3),0) -> 0.091734787 | AB22: =VLOOKUP(E22,Priors!$A$3:$C$6,2,FALSE) -> 0.15714383 | AC22: =VLOOKUP(E22,Priors!$A$3:$C$6,3,FALSE) -> 0.13222063 | AD22: =AA22*K22+(1-AA22)*AB22 -> 0.14926779 | AE22: =AA22*L22+(1-AA22)*AC22 -> 0.12336115 | AF22: 1 | AG22: 1 | AH22: =IFERROR(VLOOKUP(D22,Teams!$B$2:$I$21,7,FALSE),1) -> 1 | AI22: =AD22*AF22*AG22*AH22 -> 0.14926779 | AJ22: =AE22*AF22*AG22*AH22 -> 0.12336115 | AK22: Available | AN22: 0.003 | AO22: TRUE | AP22: 2025-07-10 | AQ22: FALSE | AS22: https://raw.githubusercontent.com/vaastav/Fantasy-Premier-League/master/data/2026-27/players_raw.csv
A23: 22 | B23: Nwaneri | C23: Ethan Nwaneri | D23: Arsenal | E23: MID | F23: 5.5 | G23: 5.5 | H23: 165 | I23: 0.23 | J23: 0.08 | K23: =IFERROR(I23*90/H23,0) -> 0.12545455 | L23: =IFERROR(J23*90/H23,0) -> 0.043636364 | M23: 0 | N23: 0 | O23: 8 | P23: 1.3 | Q23: 0 | R23: 7.09 | V23: FALSE | W23: =IFERROR(VLOOKUP(D23,Teams!$B$2:$I$21,6,FALSE),"") -> 0 | X23: None | AA23: =IFERROR(H23/(H23+Priors!$G$3),0) -> 0.1416309 | AB23: =VLOOKUP(E23,Priors!$A$3:$C$6,2,FALSE) -> 0.15714383 | AC23: =VLOOKUP(E23,Priors!$A$3:$C$6,3,FALSE) -> 0.13222063 | AD23: =AA23*K23+(1-AA23)*AB23 -> 0.15265565 | AE23: =AA23*L23+(1-AA23)*AC23 -> 0.11967436 | AF23: 1 | AG23: 1 | AH23: =IFERROR(VLOOKUP(D23,Teams!$B$2:$I$21,7,FALSE),1) -> 1 | AI23: =AD23*AF23*AG23*AH23 -> 0.15265565 | AJ23: =AE23*AF23*AG23*AH23 -> 0.11967436 | AK23: Available | AN23: 0 | AO23: TRUE | AP23: 2022-09-17 | AQ23: FALSE | AS23: https://raw.githubusercontent.com/vaastav/Fantasy-Premier-League/master/data/2026-27/players_raw.csv
A24: 23 | B24: Fábio Vieira | C24: Fábio Vieira | D24: Arsenal | E24: MID | F24: 5.5 | G24: 5.5 | H24: 0 | I24: 0 | J24: 0 | K24: =IFERROR(I24*90/H24,0) -> 0 | L24: =IFERROR(J24*90/H24,0) -> 0 | M24: 0 | N24: 0 | O24: 0 | P24: 0 | Q24: 0 | R24: 0 | V24: FALSE | W24: =IFERROR(VLOOKUP(D24,Teams!$B$2:$I$21,6,FALSE),"") -> 0 | X24: None | AA24: =IFERROR(H24/(H24+Priors!$G$3),0) -> 0 | AB24: =VLOOKUP(E24,Priors!$A$3:$C$6,2,FALSE) -> 0.15714383 | AC24: =VLOOKUP(E24,Priors!$A$3:$C$6,3,FALSE) -> 0.13222063 | AD24: =AA24*K24+(1-AA24)*AB24 -> 0.15714383 | AE24: =AA24*L24+(1-AA24)*AC24 -> 0.13222063 | AF24: 1 | AG24: 1 | AH24: =IFERROR(VLOOKUP(D24,Teams!$B$2:$I$21,7,FALSE),1) -> 1 | AI24: =AD24*AF24*AG24*AH24 -> 0.15714383 | AJ24: =AE24*AF24*AG24*AH24 -> 0.13222063 | AK24: Available | AN24: 0 | AO24: TRUE | AP24: 2022-06-21 | AQ24: FALSE | AS24: https://raw.githubusercontent.com/vaastav/Fantasy-Premier-League/master/data/2026-27/players_raw.csv
A25: 24 | B25: Nelson | C25: Reiss Nelson | D25: Arsenal | E25: MID | F25: 5.5 | G25: 5.5 | H25: 118 | I25: 0.71 | J25: 0.11 | K25: =IFERROR(I25*90/H25,0) -> 0.54152542 | L25: =IFERROR(J25*90/H25,0) -> 0.083898305 | M25: 0 | N25: 1 | O25: 13 | P25: 1.3 | Q25: 0 | R25: 17.54 | V25: FALSE | W25: =IFERROR(VLOOKUP(D25,Teams!$B$2:$I$21,6,FALSE),"") -> 0 | X25: None | AA25: =IFERROR(H25/(H25+Priors!$G$3),0) -> 0.10554562 | AB25: =VLOOKUP(E25,Priors!$A$3:$C$6,2,FALSE) -> 0.15714383 | AC25: =VLOOKUP(E25,Priors!$A$3:$C$6,3,FALSE) -> 0.13222063 | AD25: =AA25*K25+(1-AA25)*AB25 -> 0.19771362 | AE25: =AA25*L25+(1-AA25)*AC25 -> 0.12712042 | AF25: 1 | AG25: 1 | AH25: =IFERROR(VLOOKUP(D25,Teams!$B$2:$I$21,7,FALSE),1) -> 1 | AI25: =AD25*AF25*AG25*AH25 -> 0.19771362 | AJ25: =AE25*AF25*AG25*AH25 -> 0.12712042 | AK25: Available | AN25: 0 | AO25: TRUE | AP25: 2017-07-12 | AQ25: FALSE | AS25: https://raw.githubusercontent.com/vaastav/Fantasy-Premier-League/master/data/2026-27/players_raw.csv
A26: 25 | B26: Gyökeres | C26: Viktor Gyökeres | D26: Arsenal | E26: FWD | F26: 7.5 | G26: 7.5 | H26: 2217 | I26: 12.26 | J26: 1.94 | K26: =IFERROR(I26*90/H26,0) -> 0.49769959 | L26: =IFERROR(J26*90/H26,0) -> 0.078755074 | M26: 14 | N26: 1 | O26: 128 | P26: 3.6 | Q26: 26 | R26: 3.45 | S26: 2 | V26: FALSE | W26: =IFERROR(VLOOKUP(D26,Teams!$B$2:$I$21,6,FALSE),"") -> 0 | X26: None | AA26: =IFERROR(H26/(H26+Priors!$G$3),0) -> 0.68915138 | AB26: =VLOOKUP(E26,Priors!$A$3:$C$6,2,FALSE) -> 0.44625207 | AC26: =VLOOKUP(E26,Priors!$A$3:$C$6,3,FALSE) -> 0.05821726 | AD26: =AA26*K26+(1-AA26)*AB26 -> 0.4817072 | AE26: =AA26*L26+(1-AA26)*AC26 -> 0.072370923 | AF26: 1 | AG26: 1 | AH26: =IFERROR(VLOOKUP(D26,Teams!$B$2:$I$21,7,FALSE),1) -> 1 | AI26: =AD26*AF26*AG26*AH26 -> 0.4817072 | AJ26: =AE26*AF26*AG26*AH26 -> 0.072370923 | AK26: Available | AN26: 0.13 | AO26: TRUE | AP26: 2025-07-26 | AQ26: FALSE | AS26: https://raw.githubusercontent.com/vaastav/Fantasy-Premier-League/master/data/2026-27/players_raw.csv
A27: 26 | B27: Havertz | C27: Kai Havertz | D27: Arsenal | E27: FWD | F27: 7.5 | G27: 7.5 | H27: 577 | I27: 3.31 | J27: 0.64 | K27: =IFERROR(I27*90/H27,0) -> 0.51629116 | L27: =IFERROR(J27*90/H27,0) -> 0.09982669 | M27: 2 | N27: 3 | O27: 36 | P27: 3 | Q27: 7 | R27: 4.99 | V27: FALSE | W27: =IFERROR(VLOOKUP(D27,Teams!$B$2:$I$21,6,FALSE),"") -> 0 | X27: None | AA27: =IFERROR(H27/(H27+Priors!$G$3),0) -> 0.36588459 | AB27: =VLOOKUP(E27,Priors!$A$3:$C$6,2,FALSE) -> 0.44625207 | AC27: =VLOOKUP(E27,Priors!$A$3:$C$6,3,FALSE) -> 0.05821726 | AD27: =AA27*K27+(1-AA27)*AB27 -> 0.4718783 | AE27: =AA27*L27+(1-AA27)*AC27 -> 0.073441509 | AF27: 1 | AG27: 1 | AH27: =IFERROR(VLOOKUP(D27,Teams!$B$2:$I$21,7,FALSE),1) -> 1 | AI27: =AD27*AF27*AG27*AH27 -> 0.4718783 | AJ27: =AE27*AF27*AG27*AH27 -> 0.073441509 | AK27: Available | AN27: 0.04 | AO27: TRUE | AP27: 2023-06-28 | AQ27: FALSE | AS27: https://raw.githubusercontent.com/vaastav/Fantasy-Premier-League/master/data/2026-27/players_raw.csv
A28: 27 | B28: G.Jesus | C28: Gabriel Jesus | D28: Arsenal | E28: FWD | F28: 6 | G28: 6 | H28: 418 | I28: 2.71 | J28: 0.26 | K28: =IFERROR(I28*90/H28,0) -> 0.58349282 | L28: =IFERROR(J28*90/H28,0) -> 0.055980861 | M28: 3 | N28: 0 | O28: 24 | P28: 1.7 | Q28: 3 | R28: 6.46 | V28: FALSE | W28: =IFERROR(VLOOKUP(D28,Teams!$B$2:$I$21,6,FALSE),"") -> 0 | X28: None | AA28: =IFERROR(H28/(H28+Priors!$G$3),0) -> 0.29478138 | AB28: =VLOOKUP(E28,Priors!$A$3:$C$6,2,FALSE) -> 0.44625207 | AC28: =VLOOKUP(E28,Priors!$A$3:$C$6,3,FALSE) -> 0.05821726 | AD28: =AA28*K28+(1-AA28)*AB28 -> 0.48670809 | AE28: =AA28*L28+(1-AA28)*AC28 -> 0.057558011 | AF28: 1 | AG28: 1 | AH28: =IFERROR(VLOOKUP(D28,Teams!$B$2:$I$21,7,FALSE),1) -> 1 | AI28: =AD28*AF28*AG28*AH28 -> 0.48670809 | AJ28: =AE28*AF28*AG28*AH28 -> 0.057558011 | AK28: Available | AN28: 0.004 | AO28: TRUE | AP28: 2022-07-04 | AQ28: FALSE | AS28: https://raw.githubusercontent.com/vaastav/Fantasy-Premier-League/master/data/2026-27/players_raw.csv
A29: 557 | B29: Tzolis | C29: Christos Tzolis | D29: Arsenal | E29: MID | F29: 6.5 | G29: 6.5 | H29: 0 | I29: 0 | J29: 0 | K29: =IFERROR(I29*90/H29,0) -> 0 | L29: =IFERROR(J29*90/H29,0) -> 0 | M29: 0 | N29: 0 | O29: 0 | P29: 0 | Q29: 0 | R29: 0 | V29: TRUE | W29: =IFERROR(VLOOKUP(D29,Teams!$B$2:$I$21,6,FALSE),"") -> 0 | X29: None | AA29: =IFERROR(H29/(H29+Priors!$G$3),0) -> 0 | AB29: =VLOOKUP(E29,Priors!$A$3:$C$6,2,FALSE) -> 0.15714383 | AC29: =VLOOKUP(E29,Priors!$A$3:$C$6,3,FALSE) -> 0.13222063 | AD29: =AA29*K29+(1-AA29)*AB29 -> 0.15714383 | AE29: =AA29*L29+(1-AA29)*AC29 -> 0.13222063 | AF29: 1 | AG29: 1 | AH29: =IFERROR(VLOOKUP(D29,Teams!$B$2:$I$21,7,FALSE),1) -> 1 | AI29: =AD29*AF29*AG29*AH29 -> 0.15714383 | AJ29: =AE29*AF29*AG29*AH29 -> 0.13222063 | AK29: Available | AN29: 0.017 | AO29: TRUE | AP29: 2026-07-23 | AQ29: TRUE | AS29: https://raw.githubusercontent.com/vaastav/Fantasy-Premier-League/master/data/2026-27/players_raw.csv
A30: 28 | B30: Martinez | C30: Emiliano Martínez | D30: Aston Villa | E30: GK | F30: 5 | G30: 5 | H30: 2835 | I30: 0 | J30: 0.08 | K30: =IFERROR(I30*90/H30,0) -> 0 | L30: =IFERROR(J30*90/H30,0) -> 0.0025396825 | M30: 0 | N30: 1 | O30: 120 | P30: 3.8 | Q30: 32 | R30: 0 | V30: FALSE | W30: =IFERROR(VLOOKUP(D30,Teams!$B$2:$I$21,6,FALSE),"") -> 0 | X30: None | AA30: =IFERROR(H30/(H30+Priors!$G$3),0) -> 0.73924381 | AB30: =VLOOKUP(E30,Priors!$A$3:$C$6,2,FALSE) -> 0.00024013207 | AC30: =VLOOKUP(E30,Priors!$A$3:$C$6,3,FALSE) -> 0.0019810896 | AD30: =AA30*K30+(1-AA30)*AB30 -> 6.2615925e-05 | AE30: =AA30*L30+(1-AA30)*AC30 -> 0.002394026 | AF30: 1 | AG30: 1 | AH30: =IFERROR(VLOOKUP(D30,Teams!$B$2:$I$21,7,FALSE),1) -> 1 | AI30: =AD30*AF30*AG30*AH30 -> 6.2615925e-05 | AJ30: =AE30*AF30*AG30*AH30 -> 0.002394026 | AK30: Available | AN30: 0.046 | AO30: TRUE | AP30: 2020-09-16 | AQ30: FALSE | AS30: https://raw.githubusercontent.com/vaastav/Fantasy-Premier-League/master/data/2026-27/players_raw.csv
A31: 29 | B31: M.Bizot | C31: Marco Bizot | D31: Aston Villa | E31: GK | F31: 4.5 | G31: 4.5 | H31: 585 | I31: 0 | J31: 0 | K31: =IFERROR(I31*90/H31,0) -> 0 | L31: =IFERROR(J31*90/H31,0) -> 0 | M31: 0 | N31: 0 | O31: 16 | P31: 2.3 | Q31: 6 | R31: 0 | V31: FALSE | W31: =IFERROR(VLOOKUP(D31,Teams!$B$2:$I$21,6,FALSE),"") -> 0 | X31: None | AA31: =IFERROR(H31/(H31+Priors!$G$3),0) -> 0.36908517 | AB31: =VLOOKUP(E31,Priors!$A$3:$C$6,2,FALSE) -> 0.00024013207 | AC31: =VLOOKUP(E31,Priors!$A$3:$C$6,3,FALSE) -> 0.0019810896 | AD31: =AA31*K31+(1-AA31)*AB31 -> 0.00015150288 | AE31: =AA31*L31+(1-AA31)*AC31 -> 0.0012498988 | AF31: 1 | AG31: 1 | AH31: =IFERROR(VLOOKUP(D31,Teams!$B$2:$I$21,7,FALSE),1) -> 1 | AI31: =AD31*AF31*AG31*AH31 -> 0.00015150288 | AJ31: =AE31*AF31*AG31*AH31 -> 0.0012498988 | AK31: Available | AN31: 0.001 | AO31: TRUE | AP31: 2025-07-15 | AQ31: FALSE | AS31: https://raw.githubusercontent.com/vaastav/Fantasy-Premier-League/master/data/2026-27/players_raw.csv
A32: 30 | B32: Digne | C32: Lucas Digne | D32: Aston Villa | E32: DEF | F32: 4.5 | G32: 4.5 | H32: 1842 | I32: 0.67 | J32: 3.28 | K32: =IFERROR(I32*90/H32,0) -> 0.032736156 | L32: =IFERROR(J32*90/H32,0) -> 0.16026059 | M32: 0 | N32: 7 | O32: 97 | P32: 3.1 | Q32: 21 | R32: 5.52 | U32: 4 | V32: FALSE | W32: =IFERROR(VLOOKUP(D32,Teams!$B$2:$I$21,6,FALSE),"") -> 0 | X32: None | AA32: =IFERROR(H32/(H32+Priors!$G$3),0) -> 0.64813512 | AB32: =VLOOKUP(E32,Priors!$A$3:$C$6,2,FALSE) -> 0.060081391 | AC32: =VLOOKUP(E32,Priors!$A$3:$C$6,3,FALSE) -> 0.059588192 | AD32: =AA32*K32+(1-AA32)*AB32 -> 0.042357984 | AE32: =AA32*L32+(1-AA32)*AC32 -> 0.12483751 | AF32: 1 | AG32: 1 | AH32: =IFERROR(VLOOKUP(D32,Teams!$B$2:$I$21,7,FALSE),1) -> 1 | AI32: =AD32*AF32*AG32*AH32 -> 0.042357984 | AJ32: =AE32*AF32*AG32*AH32 -> 0.12483751 | AK32: Available | AN32: 0.014 | AO32: TRUE | AP32: 2022-01-13 | AQ32: FALSE | AS32: https://raw.githubusercontent.com/vaastav/Fantasy-Premier-League/master/data/2026-27/players_raw.csv
A33: 31 | B33: Konsa | C33: Ezri Konsa Ngoyo | D33: Aston Villa | E33: DEF | F33: 4.5 | G33: 4.5 | H33: 3035 | I33: 1.27 | J33: 0.59 | K33: =IFERROR(I33*90/H33,0) -> 0.037660626 | L33: =IFERROR(J33*90/H33,0) -> 0.017495881 | M33: 0 | N33: 1 | O33: 100 | P33: 2.9 | Q33: 34 | R33: 5.81 | V33: FALSE | W33: =IFERROR(VLOOKUP(D33,Teams!$B$2:$I$21,6,FALSE),"") -> 0 | X33: None | AA33: =IFERROR(H33/(H33+Priors!$G$3),0) -> 0.75216853 | AB33: =VLOOKUP(E33,Priors!$A$3:$C$6,2,FALSE) -> 0.060081391 | AC33: =VLOOKUP(E33,Priors!$A$3:$C$6,3,FALSE) -> 0.059588192 | AD33: =AA33*K33+(1-AA33)*AB33 -> 0.043217197 | AE33: =AA33*L33+(1-AA33)*AC33 -> 0.027927681 | AF33: 1 | AG33: 1 | AH33: =IFERROR(VLOOKUP(D33,Teams!$B$2:$I$21,7,FALSE),1) -> 1 | AI33: =AD33*AF33*AG33*AH33 -> 0.043217197 | AJ33: =AE33*AF33*AG33*AH33 -> 0.027927681 | AK33: Available | AN33: 0.174 | AO33: TRUE | AP33: 2019-07-11 | AQ33: FALSE | AS33: https://raw.githubusercontent.com/vaastav/Fantasy-Premier-League/master/data/2026-27/players_raw.csv
A34: 32 | B34: Cash | C34: Matty Cash | D34: Aston Villa | E34: DEF | F34: 4.5 | G34: 4.5 | H34: 3016 | I34: 1.14 | J34: 2.94 | K34: =IFERROR(I34*90/H34,0) -> 0.034018568 | L34: =IFERROR(J34*90/H34,0) -> 0.087732095 | M34: 3 | N34: 3 | O34: 117 | P34: 3.3 | Q34: 34 | R34: 5.55 | U34: 5 | V34: FALSE | W34: =IFERROR(VLOOKUP(D34,Teams!$B$2:$I$21,6,FALSE),"") -> 0 | X34: None | AA34: =IFERROR(H34/(H34+Priors!$G$3),0) -> 0.75099602 | AB34: =VLOOKUP(E34,Priors!$A$3:$C$6,2,FALSE) -> 0.060081391 | AC34: =VLOOKUP(E34,Priors!$A$3:$C$6,3,FALSE) -> 0.059588192 | AD34: =AA34*K34+(1-AA34)*AB34 -> 0.040508315 | AE34: =AA34*L34+(1-AA34)*AC34 -> 0.080724151 | AF34: 1 | AG34: 1 | AH34: =IFERROR(VLOOKUP(D34,Teams!$B$2:$I$21,7,FALSE),1) -> 1 | AI34: =AD34*AF34*AG34*AH34 -> 0.040508315 | AJ34: =AE34*AF34*AG34*AH34 -> 0.080724151 | AK34: Available | AN34: 0.078 | AO34: TRUE | AP34: 2020-09-03 | AQ34: TRUE | AS34: https://raw.githubusercontent.com/vaastav/Fantasy-Premier-League/master/data/2026-27/players_raw.csv
A35: 33 | B35: Mings | C35: Tyrone Mings | D35: Aston Villa | E35: DEF | F35: 4.5 | G35: 4.5 | H35: 1322 | I35: 1.3 | J35: 0.42 | K35: =IFERROR(I35*90/H35,0) -> 0.088502269 | L35: =IFERROR(J35*90/H35,0) -> 0.028593041 | M35: 0 | N35: 1 | O35: 50 | P35: 2.9 | Q35: 15 | R35: 7.28 | V35: FALSE | W35: =IFERROR(VLOOKUP(D35,Teams!$B$2:$I$21,6,FALSE),"") -> 0 | X35: None | AA35: =IFERROR(H35/(H35+Priors!$G$3),0) -> 0.56933678 | AB35: =VLOOKUP(E35,Priors!$A$3:$C$6,2,FALSE) -> 0.060081391 | AC35: =VLOOKUP(E35,Priors!$A$3:$C$6,3,FALSE) -> 0.059588192 | AD35: =AA35*K35+(1-AA35)*AB35 -> 0.076262442 | AE35: =AA35*L35+(1-AA35)*AC35 -> 0.041941512 | AF35: 1 | AG35: 1 | AH35: =IFERROR(VLOOKUP(D35,Teams!$B$2:$I$21,7,FALSE),1) -> 1 | AI35: =AD35*AF35*AG35*AH35 -> 0.076262442 | AJ35: =AE35*AF35*AG35*AH35 -> 0.041941512 | AK35: Available | AN35: 0.002 | AO35: TRUE | AP35: 2019-07-08 | AQ35: FALSE | AS35: https://raw.githubusercontent.com/vaastav/Fantasy-Premier-League/master/data/2026-27/players_raw.csv
A36: 34 | B36: Pau | C36: Pau Torres | D36: Aston Villa | E36: DEF | F36: 4.5 | G36: 4.5 | H36: 1673 | I36: 1.33 | J36: 0.39 | K36: =IFERROR(I36*90/H36,0) -> 0.071548117 | L36: =IFERROR(J36*90/H36,0) -> 0.020980275 | M36: 0 | N36: 2 | O36: 64 | P36: 3 | Q36: 18 | R36: 6.03 | V36: FALSE | W36: =IFERROR(VLOOKUP(D36,Teams!$B$2:$I$21,6,FALSE),"") -> 0 | X36: None | AA36: =IFERROR(H36/(H36+Priors!$G$3),0) -> 0.62588851 | AB36: =VLOOKUP(E36,Priors!$A$3:$C$6,2,FALSE) -> 0.060081391 | AC36: =VLOOKUP(E36,Priors!$A$3:$C$6,3,FALSE) -> 0.059588192 | AD36: =AA36*K36+(1-AA36)*AB36 -> 0.067258283 | AE36: =AA36*L36+(1-AA36)*AC36 -> 0.03542394 | AF36: 1 | AG36: 1 | AH36: =IFERROR(VLOOKUP(D36,Teams!$B$2:$I$21,7,FALSE),1) -> 1 | AI36: =AD36*AF36*AG36*AH36 -> 0.067258283 | AJ36: =AE36*AF36*AG36*AH36 -> 0.03542394 | AK36: Available | AN36: 0.002 | AO36: TRUE | AP36: 2023-07-12 | AQ36: FALSE | AS36: https://raw.githubusercontent.com/vaastav/Fantasy-Premier-League/master/data/2026-27/players_raw.csv
A37: 35 | B37: Bogarde | C37: Lamare Bogarde | D37: Aston Villa | E37: MID | F37: 5 | G37: 5 | H37: 1042 | I37: 0 | J37: 0.2 | K37: =IFERROR(I37*90/H37,0) -> 0 | L37: =IFERROR(J37*90/H37,0) -> 0.017274472 | M37: 0 | N37: 0 | O37: 40 | P37: 1.4 | Q37: 11 | R37: 5.18 | V37: FALSE | W37: =IFERROR(VLOOKUP(D37,Teams!$B$2:$I$21,6,FALSE),"") -> 0 | X37: None | AA37: =IFERROR(H37/(H37+Priors!$G$3),0) -> 0.51028404 | AB37: =VLOOKUP(E37,Priors!$A$3:$C$6,2,FALSE) -> 0.15714383 | AC37: =VLOOKUP(E37,Priors!$A$3:$C$6,3,FALSE) -> 0.13222063 | AD37: =AA37*K37+(1-AA37)*AB37 -> 0.076955843 | AE37: =AA37*L37+(1-AA37)*AC37 -> 0.07356544 | AF37: 1 | AG37: 1 | AH37: =IFERROR(VLOOKUP(D37,Teams!$B$2:$I$21,7,FALSE),1) -> 1 | AI37: =AD37*AF37*AG37*AH37 -> 0.076955843 | AJ37: =AE37*AF37*AG37*AH37 -> 0.07356544 | AK37: Available | AN37: 0.001 | AO37: TRUE | AP37: 2021-01-07 | AQ37: FALSE | AS37: https://raw.githubusercontent.com/vaastav/Fantasy-Premier-League/master/data/2026-27/players_raw.csv
A38: 36 | B38: Maatsen | C38: Ian Maatsen | D38: Aston Villa | E38: DEF | F38: 4.5 | G38: 4.5 | H38: 1590 | I38: 1.26 | J38: 2.39 | K38: =IFERROR(I38*90/H38,0) -> 0.071320755 | L38: =IFERROR(J38*90/H38,0) -> 0.13528302 | M38: 0 | N38: 1 | O38: 54 | P38: 1.8 | Q38: 17 | R38: 7.25 | V38: FALSE | W38: =IFERROR(VLOOKUP(D38,Teams!$B$2:$I$21,6,FALSE),"") -> 0 | X38: None | AA38: =IFERROR(H38/(H38+Priors!$G$3),0) -> 0.61389961 | AB38: =VLOOKUP(E38,Priors!$A$3:$C$6,2,FALSE) -> 0.060081391 | AC38: =VLOOKUP(E38,Priors!$A$3:$C$6,3,FALSE) -> 0.059588192 | AD38: =AA38*K38+(1-AA38)*AB38 -> 0.066981232 | AE38: =AA38*L38+(1-AA38)*AC38 -> 0.10605722 | AF38: 1 | AG38: 1 | AH38: =IFERROR(VLOOKUP(D38,Teams!$B$2:$I$21,7,FALSE),1) -> 1 | AI38: =AD38*AF38*AG38*AH38 -> 0.066981232 | AJ38: =AE38*AF38*AG38*AH38 -> 0.10605722 | AK38: Available | AN38: 0.006 | AO38: TRUE | AP38: 2024-06-28 | AQ38: FALSE | AS38: https://raw.githubusercontent.com/vaastav/Fantasy-Premier-League/master/data/2026-27/players_raw.csv
A39: 37 | B39: Lindelöf | C39: Victor Lindelöf | D39: Aston Villa | E39: DEF | F39: 4.5 | G39: 4.5 | H39: 942 | I39: 0.28 | J39: 0.1 | K39: =IFERROR(I39*90/H39,0) -> 0.026751592 | L39: =IFERROR(J39*90/H39,0) -> 0.0095541401 | M39: 0 | N39: 1 | O39: 29 | P39: 1.7 | Q39: 11 | R39: 5.16 | V39: FALSE | W39: =IFERROR(VLOOKUP(D39,Teams!$B$2:$I$21,6,FALSE),"") -> 0 | X39: None | AA39: =IFERROR(H39/(H39+Priors!$G$3),0) -> 0.48506694 | AB39: =VLOOKUP(E39,Priors!$A$3:$C$6,2,FALSE) -> 0.060081391 | AC39: =VLOOKUP(E39,Priors!$A$3:$C$6,3,FALSE) -> 0.059588192 | AD39: =AA39*K39+(1-AA39)*AB39 -> 0.043914208 | AE39: =AA39*L39+(1-AA39)*AC39 -> 0.035318327 | AF39: 1 | AG39: 1 | AH39: =IFERROR(VLOOKUP(D39,Teams!$B$2:$I$21,7,FALSE),1) -> 1 | AI39: =AD39*AF39*AG39*AH39 -> 0.043914208 | AJ39: =AE39*AF39*AG39*AH39 -> 0.035318327 | AK39: Available | AN39: 0.002 | AO39: TRUE | AP39: 2025-09-01 | AQ39: FALSE | AS39: https://raw.githubusercontent.com/vaastav/Fantasy-Premier-League/master/data/2026-27/players_raw.csv
A40: 38 | B40: A.García | C40: Andrés García | D40: Aston Villa | E40: DEF | F40: 4 | G40: 4 | H40: 83 | I40: 0 | J40: 0.01 | K40: =IFERROR(I40*90/H40,0) -> 0 | L40: =IFERROR(J40*90/H40,0) -> 0.010843373 | M40: 0 | N40: 0 | O40: 5 | P40: 0.8 | Q40: 1 | R40: 10.84 | V40: TRUE | W40: =IFERROR(VLOOKUP(D40,Teams!$B$2:$I$21,6,FALSE),"") -> 0 | X40: None | AA40: =IFERROR(H40/(H40+Priors!$G$3),0) -> 0.076638966 | AB40: =VLOOKUP(E40,Priors!$A$3:$C$6,2,FALSE) -> 0.060081391 | AC40: =VLOOKUP(E40,Priors!$A$3:$C$6,3,FALSE) -> 0.059588192 | AD40: =AA40*K40+(1-AA40)*AB40 -> 0.055476816 | AE40: =AA40*L40+(1-AA40)*AC40 -> 0.055852439 | AF40: 1 | AG40: 1 | AH40: =IFERROR(VLOOKUP(D40,Teams!$B$2:$I$21,7,FALSE),1) -> 1 | AI40: =AD40*AF40*AG40*AH40 -> 0.055476816 | AJ40: =AE40*AF40*AG40*AH40 -> 0.055852439 | AK40: Available | AN40: 0.015 | AO40: TRUE | AP40: None | AQ40: FALSE | AS40: https://raw.githubusercontent.com/vaastav/Fantasy-Premier-League/master/data/2026-27/players_raw.csv
...

Sheet Teams
A1: Team ID | B1: Team | C1: Short | D1: FPL Strength Home | E1: FPL Strength Away | F1: Promoted 26/27? | G1: New Manager? | H1: Team Attack Adj | I1: Team Defence Adj | J1: Notes | K1: Source URL
A2: 1 | B2: Arsenal | C2: ARS | D2: 4 | E2: 5 | F2: FALSE | H2: 1 | I2: 1 | K2: https://raw.githubusercontent.com/vaastav/Fantasy-Premier-League/master/data/2026-27/teams.csv
A3: 2 | B3: Aston Villa | C3: AVL | D3: 3 | E3: 4 | F3: FALSE | H3: 1 | I3: 1 | K3: https://raw.githubusercontent.com/vaastav/Fantasy-Premier-League/master/data/2026-27/teams.csv
A4: 3 | B4: Bournemouth | C4: BOU | D4: 3 | E4: 3 | F4: FALSE | H4: 1 | I4: 1 | K4: https://raw.githubusercontent.com/vaastav/Fantasy-Premier-League/master/data/2026-27/teams.csv
A5: 4 | B5: Brentford | C5: BRE | D5: 3 | E5: 3 | F5: FALSE | H5: 1 | I5: 1 | K5: https://raw.githubusercontent.com/vaastav/Fantasy-Premier-League/master/data/2026-27/teams.csv
A6: 5 | B6: Brighton | C6: BHA | D6: 2 | E6: 3 | F6: FALSE | H6: 1 | I6: 1 | K6: https://raw.githubusercontent.com/vaastav/Fantasy-Premier-League/master/data/2026-27/teams.csv
A7: 6 | B7: Chelsea | C7: CHE | D7: 4 | E7: 4 | F7: FALSE | H7: 1 | I7: 1 | K7: https://raw.githubusercontent.com/vaastav/Fantasy-Premier-League/master/data/2026-27/teams.csv
A8: 7 | B8: Coventry City | C8: COV | D8: 2 | E8: 2 | F8: TRUE | H8: 1 | I8: 1 | K8: https://raw.githubusercontent.com/vaastav/Fantasy-Premier-League/master/data/2026-27/teams.csv
A9: 8 | B9: Crystal Palace | C9: CRY | D9: 3 | E9: 3 | F9: FALSE | H9: 1 | I9: 1 | K9: https://raw.githubusercontent.com/vaastav/Fantasy-Premier-League/master/data/2026-27/teams.csv
A10: 9 | B10: Everton | C10: EVE | D10: 3 | E10: 3 | F10: FALSE | H10: 1 | I10: 1 | K10: https://raw.githubusercontent.com/vaastav/Fantasy-Premier-League/master/data/2026-27/teams.csv
A11: 10 | B11: Fulham | C11: FUL | D11: 2 | E11: 3 | F11: FALSE | H11: 1 | I11: 1 | K11: https://raw.githubusercontent.com/vaastav/Fantasy-Premier-League/master/data/2026-27/teams.csv
A12: 11 | B12: Hull City | C12: HUL | D12: 2 | E12: 2 | F12: TRUE | H12: 1 | I12: 1 | K12: https://raw.githubusercontent.com/vaastav/Fantasy-Premier-League/master/data/2026-27/teams.csv
A13: 12 | B13: Ipswich Town | C13: IPS | D13: 2 | E13: 2 | F13: TRUE | H13: 1 | I13: 1 | K13: https://raw.githubusercontent.com/vaastav/Fantasy-Premier-League/master/data/2026-27/teams.csv
... A21: 20 | B21: Sunderland | C21: SUN | D21: 2 | E21: 3 | F21: FALSE | H21: 1 | I21: 1 | K21: https://raw.githubusercontent.com/vaastav/Fantasy-Premier-League/master/data/2026-27/teams.csv

Sheet Priors
A1: POSITIONAL PRIORS | F1: MODEL ASSUMPTIONS | I1: MODEL NOTES
A2: Position | B2: xG90 prior | C2: xA90 prior | D2: Method | F2: Assumption | G2: Value | I2: Raw current-season FPL universe: 567 players
A3: GK | B3: =IFERROR(SUMIFS(Players!$I$2:$I$568,Players!$E$2:$E$568,A3)*90/SUMIFS(Players!$H$2:$H$568,Players!$E$2:$E$568,A3),0) -> 0.00024013207 | C3: =IFERROR(SUMIFS(Players!$J$2:$J$568,Players!$E$2:$E$568,A3)*90/SUMIFS(Players!$H$2:$H$568,Players!$E$2:$E$568,A3),0) -> 0.0019810896 | D3: Minute-weighted 25/26 history | F3: Shrinkage minutes (k) | G3: 1000 | I3: Historical 25/26 fields are the preseason FPL snapshot values.
A4: DEF | B4: =IFERROR(SUMIFS(Players!$I$2:$I$568,Players!$E$2:$E$568,A4)*90/SUMIFS(Players!$H$2:$H$568,Players!$E$2:$E$568,A4),0) -> 0.060081391 | C4: =IFERROR(SUMIFS(Players!$J$2:$J$568,Players!$E$2:$E$568,A4)*90/SUMIFS(Players!$H$2:$H$568,Players!$E$2:$E$568,A4),0) -> 0.059588192 | D4: Minute-weighted 25/26 history | F4: Projection horizon (GWs) | G4: 6 | I4: Players with no PL history shrink fully toward the positional prior.
A5: MID | B5: =IFERROR(SUMIFS(Players!$I$2:$I$568,Players!$E$2:$E$568,A5)*90/SUMIFS(Players!$H$2:$H$568,Players!$E$2:$E$568,A5),0) -> 0.15714383 | C5: =IFERROR(SUMIFS(Players!$J$2:$J$568,Players!$E$2:$E$568,A5)*90/SUMIFS(Players!$H$2:$H$568,Players!$E$2:$E$568,A5),0) -> 0.13222063 | D5: Minute-weighted 25/26 history | F5: Default league adj | G5: 1 | I5: Sample Weight = minutes / (minutes + k).
A6: FWD | B6: =IFERROR(SUMIFS(Players!$I$2:$I$568,Players!$E$2:$E$568,A6)*90/SUMIFS(Players!$H$2:$H$568,Players!$E$2:$E$568,A6),0) -> 0.44625207 | C6: =IFERROR(SUMIFS(Players!$J$2:$J$568,Players!$E$2:$E$568,A6)*90/SUMIFS(Players!$H$2:$H$568,Players!$E$2:$E$568,A6),0) -> 0.05821726 | D6: Minute-weighted 25/26 history | F6: Default role adj | G6: 1 | I6: League/role adjustments are explicit judgement inputs, default 1.00.
F7: Snapshot date | G7: 2026-08-18 | I7: Team adjustment links to the Teams sheet, default 1.00.
I8: Yellow = assumption/input; blue text = hardcoded data.
I9: Green text = links to another worksheet; black = formulas.
I10: Fixture market xG fields are intentionally blank for later bookmaker work.

Sheet Fixtures
A1: GW | B1: Fixture ID | C1: Kickoff UTC | D1: Team | E1: Opponent | F1: H/A | G1: Official FDR | H1: Team ID | I1: Opponent ID | J1: Market Team xG | K1: Market Opp xG | L1: CS Prob | M1: Attack Fixture Adj | N1: Def Fixture Adj | O1: Notes | P1: Source URL
A2: 1 | B2: 1 | C2: 46255.792 | D2: Coventry City | E2: Arsenal | F2: A | G2: 5 | H2: 7 | I2: 1 | L2: =IF(K2="","",EXP(-K2)) | M2: 1 | N2: 1 | P2: https://raw.githubusercontent.com/vaastav/Fantasy-Premier-League/master/data/2026-27/fixtures.csv
A3: 1 | B3: 1 | C3: 46255.792 | D3: Arsenal | E3: Coventry City | F3: H | G3: 2 | H3: 1 | I3: 7 | L3: =IF(K3="","",EXP(-K3)) | M3: 1 | N3: 1 | P3: https://raw.githubusercontent.com/vaastav/Fantasy-Premier-League/master/data/2026-27/fixtures.csv
A4: 1 | B4: 2 | C4: 46256.688 | D4: Spurs | E4: Brentford | F4: A | G4: 3 | H4: 19 | I4: 4 | L4: =IF(K4="","",EXP(-K4)) | M4: 1 | N4: 1 | P4: https://raw.githubusercontent.com/vaastav/Fantasy-Premier-League/master/data/2026-27/fixtures.csv
A5: 1 | B5: 2 | C5: 46256.688 | D5: Brentford | E5: Spurs | F5: H | G5: 3 | H5: 4 | I5: 19 | L5: =IF(K5="","",EXP(-K5)) | M5: 1 | N5: 1 | P5: https://raw.githubusercontent.com/vaastav/Fantasy-Premier-League/master/data/2026-27/fixtures.csv
A6: 1 | B6: 3 | C6: 46256.583 | D6: Crystal Palace | E6: Everton | F6: A | G6: 3 | H6: 8 | I6: 9 | L6: =IF(K6="","",EXP(-K6)) | M6: 1 | N6: 1 | P6: https://raw.githubusercontent.com/vaastav/Fantasy-Premier-League/master/data/2026-27/fixtures.csv
A7: 1 | B7: 3 | C7: 46256.583 | D7: Everton | E7: Crystal Palace | F7: H | G7: 3 | H7: 9 | I7: 8 | L7: =IF(K7="","",EXP(-K7)) | M7: 1 | N7: 1 | P7: https://raw.githubusercontent.com/vaastav/Fantasy-Premier-League/master/data/2026-27/fixtures.csv
A8: 1 | B8: 4 | C8: 46256.479 | D8: Man Utd | E8: Hull City | F8: A | G8: 2 | H8: 16 | I8: 11 | L8: =IF(K8="","",EXP(-K8)) | M8: 1 | N8: 1 | P8: https://raw.githubusercontent.com/vaastav/Fantasy-Premier-League/master/data/2026-27/fixtures.csv
A9: 1 | B9: 4 | C9: 46256.479 | D9: Hull City | E9: Man Utd | F9: H | G9: 4 | H9: 11 | I9: 16 | L9: =IF(K9="","",EXP(-K9)) | M9: 1 | N9: 1 | P9: https://raw.githubusercontent.com/vaastav/Fantasy-Premier-League/master/data/2026-27/fixtures.csv
A10: 1 | B10: 5 | C10: 46256.583 | D10: Sunderland | E10: Ipswich Town | F10: A | G10: 2 | H10: 20 | I10: 12 | L10: =IF(K10="","",EXP(-K10)) | M10: 1 | N10: 1 | P10: https://raw.githubusercontent.com/vaastav/Fantasy-Premier-League/master/data/2026-27/fixtures.csv
A11: 1 | B11: 5 | C11: 46256.583 | D11: Ipswich Town | E11: Sunderland | F11: H | G11: 2 | H11: 12 | I11: 20 | L11: =IF(K11="","",EXP(-K11)) | M11: 1 | N11: 1 | P11: https://raw.githubusercontent.com/vaastav/Fantasy-Premier-League/master/data/2026-27/fixtures.csv
A12: 1 | B12: 6 | C12: 46256.583 | D12: Leeds | E12: Nott'm Forest | F12: A | G12: 3 | H12: 13 | I12: 18 | L12: =IF(K12="","",EXP(-K12)) | M12: 1 | N12: 1 | P12: https://raw.githubusercontent.com/vaastav/Fantasy-Premier-League/master/data/2026-27/fixtures.csv
A13: 1 | B13: 6 | C13: 46256.583 | D13: Nott'm Forest | E13: Leeds | F13: H | G13: 2 | H13: 18 | I13: 13 | L13: =IF(K13="","",EXP(-K13)) | M13: 1 | N13: 1 | P13: https://raw.githubusercontent.com/vaastav/Fantasy-Premier-League/master/data/2026-27/fixtures.csv
... A761: 38 | B761: 380 | C761: 46537.625 | D761: Sunderland | E761: Man City | F761: H | G761: 4 | H761: 20 | I761: 15 | L761: =IF(K761="","",EXP(-K761)) | M761: 1 | N761: 1 | P761: https://raw.githubusercontent.com/vaastav/Fantasy-Premier-League/master/data/2026-27/fixtures.csv

Sheet Projections
A1: GW | B1: Player ID | C1: Player | D1: Team | E1: Position | F1: Current Price (£m) | G1: Expected Mins | H1: Adj xG90 | I1: Adj xA90 | J1: Fixture Att Adj | K1: Fixture CS Prob | L1: Fixture xG | M1: Fixture xA | N1: Appearance Pts | O1: Goal Pts | P1: Assist Pts | Q1: CS Pts | R1: DC Pts | S1: Bonus Pts | T1: Total xPts
A3: Intentionally left as the next modelling layer: populate once minutes + point-conversion logic are agreed.

Sheet Squad
A1: Player | B1: Team | C1: Position | D1: Current Price (£m) | E1: Starter? | F1: Captain? | G1: Start Prob | H1: Exp Mins | I1: Adj xG90 | J1: Adj xA90 | K1: 6GW xPts | L1: Notes
B2: =IFERROR(VLOOKUP($A2,Players!$C$2:$AJ$568,2,FALSE),"") | C2: =IFERROR(VLOOKUP($A2,Players!$C$2:$AJ$568,3,FALSE),"") | D2: =IFERROR(VLOOKUP($A2,Players!$C$2:$AJ$568,5,FALSE),"") | G2: =IFERROR(VLOOKUP($A2,Players!$C$2:$AJ$568,23,FALSE),"") | H2: =IFERROR(VLOOKUP($A2,Players!$C$2:$AJ$568,24,FALSE),"") | I2: =IFERROR(VLOOKUP($A2,Players!$C$2:$AJ$568,33,FALSE),"") | J2: =IFERROR(VLOOKUP($A2,Players!$C$2:$AJ$568,34,FALSE),"")
B3: =IFERROR(VLOOKUP($A3,Players!$C$2:$AJ$568,2,FALSE),"") | C3: =IFERROR(VLOOKUP($A3,Players!$C$2:$AJ$568,3,FALSE),"") | D3: =IFERROR(VLOOKUP($A3,Players!$C$2:$AJ$568,5,FALSE),"") | G3: =IFERROR(VLOOKUP($A3,Players!$C$2:$AJ$568,23,FALSE),"") | H3: =IFERROR(VLOOKUP($A3,Players!$C$2:$AJ$568,24,FALSE),"") | I3: =IFERROR(VLOOKUP($A3,Players!$C$2:$AJ$568,33,FALSE),"") | J3: =IFERROR(VLOOKUP($A3,Players!$C$2:$AJ$568,34,FALSE),"")
B4: =IFERROR(VLOOKUP($A4,Players!$C$2:$AJ$568,2,FALSE),"") | C4: =IFERROR(VLOOKUP($A4,Players!$C$2:$AJ$568,3,FALSE),"") | D4: =IFERROR(VLOOKUP($A4,Players!$C$2:$AJ$568,5,FALSE),"") | G4: =IFERROR(VLOOKUP($A4,Players!$C$2:$AJ$568,23,FALSE),"") | H4: =IFERROR(VLOOKUP($A4,Players!$C$2:$AJ$568,24,FALSE),"") | I4: =IFERROR(VLOOKUP($A4,Players!$C$2:$AJ$568,33,FALSE),"") | J4: =IFERROR(VLOOKUP($A4,Players!$C$2:$AJ$568,34,FALSE),"")
B5: =IFERROR(VLOOKUP($A5,Players!$C$2:$AJ$568,2,FALSE),"") | C5: =IFERROR(VLOOKUP($A5,Players!$C$2:$AJ$568,3,FALSE),"") | D5: =IFERROR(VLOOKUP($A5,Players!$C$2:$AJ$568,5,FALSE),"") | G5: =IFERROR(VLOOKUP($A5,Players!$C$2:$AJ$568,23,FALSE),"") | H5: =IFERROR(VLOOKUP($A5,Players!$C$2:$AJ$568,24,FALSE),"") | I5: =IFERROR(VLOOKUP($A5,Players!$C$2:$AJ$568,33,FALSE),"") | J5: =IFERROR(VLOOKUP($A5,Players!$C$2:$AJ$568,34,FALSE),"")
B6: =IFERROR(VLOOKUP($A6,Players!$C$2:$AJ$568,2,FALSE),"") | C6: =IFERROR(VLOOKUP($A6,Players!$C$2:$AJ$568,3,FALSE),"") | D6: =IFERROR(VLOOKUP($A6,Players!$C$2:$AJ$568,5,FALSE),"") | G6: =IFERROR(VLOOKUP($A6,Players!$C$2:$AJ$568,23,FALSE),"") | H6: =IFERROR(VLOOKUP($A6,Players!$C$2:$AJ$568,24,FALSE),"") | I6: =IFERROR(VLOOKUP($A6,Players!$C$2:$AJ$568,33,FALSE),"") | J6: =IFERROR(VLOOKUP($A6,Players!$C$2:$AJ$568,34,FALSE),"")
B7: =IFERROR(VLOOKUP($A7,Players!$C$2:$AJ$568,2,FALSE),"") | C7: =IFERROR(VLOOKUP($A7,Players!$C$2:$AJ$568,3,FALSE),"") | D7: =IFERROR(VLOOKUP($A7,Players!$C$2:$AJ$568,5,FALSE),"") | G7: =IFERROR(VLOOKUP($A7,Players!$C$2:$AJ$568,23,FALSE),"") | H7: =IFERROR(VLOOKUP($A7,Players!$C$2:$AJ$568,24,FALSE),"") | I7: =IFERROR(VLOOKUP($A7,Players!$C$2:$AJ$568,33,FALSE),"") | J7: =IFERROR(VLOOKUP($A7,Players!$C$2:$AJ$568,34,FALSE),"")
B8: =IFERROR(VLOOKUP($A8,Players!$C$2:$AJ$568,2,FALSE),"") | C8: =IFERROR(VLOOKUP($A8,Players!$C$2:$AJ$568,3,FALSE),"") | D8: =IFERROR(VLOOKUP($A8,Players!$C$2:$AJ$568,5,FALSE),"") | G8: =IFERROR(VLOOKUP($A8,Players!$C$2:$AJ$568,23,FALSE),"") | H8: =IFERROR(VLOOKUP($A8,Players!$C$2:$AJ$568,24,FALSE),"") | I8: =IFERROR(VLOOKUP($A8,Players!$C$2:$AJ$568,33,FALSE),"") | J8: =IFERROR(VLOOKUP($A8,Players!$C$2:$AJ$568,34,FALSE),"")
B9: =IFERROR(VLOOKUP($A9,Players!$C$2:$AJ$568,2,FALSE),"") | C9: =IFERROR(VLOOKUP($A9,Players!$C$2:$AJ$568,3,FALSE),"") | D9: =IFERROR(VLOOKUP($A9,Players!$C$2:$AJ$568,5,FALSE),"") | G9: =IFERROR(VLOOKUP($A9,Players!$C$2:$AJ$568,23,FALSE),"") | H9: =IFERROR(VLOOKUP($A9,Players!$C$2:$AJ$568,24,FALSE),"") | I9: =IFERROR(VLOOKUP($A9,Players!$C$2:$AJ$568,33,FALSE),"") | J9: =IFERROR(VLOOKUP($A9,Players!$C$2:$AJ$568,34,FALSE),"")
B10: =IFERROR(VLOOKUP($A10,Players!$C$2:$AJ$568,2,FALSE),"") | C10: =IFERROR(VLOOKUP($A10,Players!$C$2:$AJ$568,3,FALSE),"") | D10: =IFERROR(VLOOKUP($A10,Players!$C$2:$AJ$568,5,FALSE),"") | G10: =IFERROR(VLOOKUP($A10,Players!$C$2:$AJ$568,23,FALSE),"") | H10: =IFERROR(VLOOKUP($A10,Players!$C$2:$AJ$568,24,FALSE),"") | I10: =IFERROR(VLOOKUP($A10,Players!$C$2:$AJ$568,33,FALSE),"") | J10: =IFERROR(VLOOKUP($A10,Players!$C$2:$AJ$568,34,FALSE),"")
B11: =IFERROR(VLOOKUP($A11,Players!$C$2:$AJ$568,2,FALSE),"") | C11: =IFERROR(VLOOKUP($A11,Players!$C$2:$AJ$568,3,FALSE),"") | D11: =IFERROR(VLOOKUP($A11,Players!$C$2:$AJ$568,5,FALSE),"") | G11: =IFERROR(VLOOKUP($A11,Players!$C$2:$AJ$568,23,FALSE),"") | H11: =IFERROR(VLOOKUP($A11,Players!$C$2:$AJ$568,24,FALSE),"") | I11: =IFERROR(VLOOKUP($A11,Players!$C$2:$AJ$568,33,FALSE),"") | J11: =IFERROR(VLOOKUP($A11,Players!$C$2:$AJ$568,34,FALSE),"")
B12: =IFERROR(VLOOKUP($A12,Players!$C$2:$AJ$568,2,FALSE),"") | C12: =IFERROR(VLOOKUP($A12,Players!$C$2:$AJ$568,3,FALSE),"") | D12: =IFERROR(VLOOKUP($A12,Players!$C$2:$AJ$568,5,FALSE),"") | G12: =IFERROR(VLOOKUP($A12,Players!$C$2:$AJ$568,23,FALSE),"") | H12: =IFERROR(VLOOKUP($A12,Players!$C$2:$AJ$568,24,FALSE),"") | I12: =IFERROR(VLOOKUP($A12,Players!$C$2:$AJ$568,33,FALSE),"") | J12: =IFERROR(VLOOKUP($A12,Players!$C$2:$AJ$568,34,FALSE),"")
B13: =IFERROR(VLOOKUP($A13,Players!$C$2:$AJ$568,2,FALSE),"") | C13: =IFERROR(VLOOKUP($A13,Players!$C$2:$AJ$568,3,FALSE),"") | D13: =IFERROR(VLOOKUP($A13,Players!$C$2:$AJ$568,5,FALSE),"") | G13: =IFERROR(VLOOKUP($A13,Players!$C$2:$AJ$568,23,FALSE),"") | H13: =IFERROR(VLOOKUP($A13,Players!$C$2:$AJ$568,24,FALSE),"") | I13: =IFERROR(VLOOKUP($A13,Players!$C$2:$AJ$568,33,FALSE),"") | J13: =IFERROR(VLOOKUP($A13,Players!$C$2:$AJ$568,34,FALSE),"")
... B16: =IFERROR(VLOOKUP($A16,Players!$C$2:$AJ$568,2,FALSE),"") | C16: =IFERROR(VLOOKUP($A16,Players!$C$2:$AJ$568,3,FALSE),"") | D16: =IFERROR(VLOOKUP($A16,Players!$C$2:$AJ$568,5,FALSE),"") | G16: =IFERROR(VLOOKUP($A16,Players!$C$2:$AJ$568,23,FALSE),"") | H16: =IFERROR(VLOOKUP($A16,Players!$C$2:$AJ$568,24,FALSE),"") | I16: =IFERROR(VLOOKUP($A16,Players!$C$2:$AJ$568,33,FALSE),"") | J16: =IFERROR(VLOOKUP($A16,Players!$C$2:$AJ$568,34,FALSE),"")

Sheet Lists
A1: Teams | B1: Positions | C1: Boolean | D1: Role Change | E1: Status Code
A2: Arsenal | B2: GK | C2: FALSE | D2: None | E2: a
A3: Aston Villa | B3: DEF | C3: TRUE | D3: More advanced | E3: d
A4: Bournemouth | B4: MID | D4: Deeper | E4: i
A5: Brentford | B5: FWD | D5: Rotation risk | E5: s
A6: Brighton | D6: Unknown | E6: u
A7: Chelsea
A8: Coventry City
A9: Crystal Palace
A10: Everton
A11: Fulham
A12: Hull City
A13: Ipswich Town
A14: Leeds
A15: Liverpool
A16: Man City
A17: Man Utd
A18: Newcastle
... A21: Sunderland
