Workbook

Sheet Dashboard
A1: FPL 2026/27 Model — v0.5 Team + Fixture Engine
A3: Snapshot | B3: 19 Aug 2026 | D3: Fixture | E3: Fair H | F3: Fair D | G3: Fair A | H3: Home xG | I3: Away xG
A4: GW1 market coverage | B4: 10 / 10 fixtures | D4: Arsenal v Coventry City | E4: 0.82429501 | F4: 0.12364425 | G4: 0.052060738 | H4: 2.6529358 | I4: 0.52865869
A5: Market anchor | B5: Oddschecker 1X2 best-price consensus | D5: Hull City v Man Utd | E5: 0.10324484 | F5: 0.19616519 | G5: 0.70058997 | H5: 0.60545883 | I5: 1.9843124
A6: De-vig | B6: Yes — normalize implied probs to 100% | D6: Ipswich Town v Sunderland | E6: 0.34958111 | F6: 0.28789033 | G6: 0.36252856 | H6: 1.1088257 | I6: 1.1347602
A7: Market xG method | B7: Independent Poisson fit to fair 1X2 | D7: Everton v Crystal Palace | E7: 0.43391067 | F7: 0.27894257 | G7: 0.28714676 | H7: 1.3042478 | I7: 1.0054212
A8: Default market weight | B8: 100% where market exists | D8: Nott'm Forest v Leeds | E8: 0.41309359 | F8: 0.28031351 | G8: 0.3065929 | H8: 1.266981 | I8: 1.0502507
A9: Structural model | B9: Parallel diagnostic / future fallback | D9: Brentford v Spurs | E9: 0.39069767 | F9: 0.26046512 | G9: 0.34883721 | H9: 1.3720338 | I9: 1.28186
A10: Final FPL xPts | B10: Not yet — v0.6 | D10: Man City v Bournemouth | E10: 0.65326633 | F10: 0.1959799 | G10: 0.15075377 | H10: 2.1387928 | I10: 0.91917821
D11: Brighton v Aston Villa | E11: 0.42603978 | F11: 0.25786618 | G11: 0.31609403 | H11: 1.4525482 | I11: 1.2147039
D12: Newcastle v Liverpool | E12: 0.26324671 | F12: 0.24974688 | G12: 0.48700641 | H12: 1.1006915 | I12: 1.5903535
D13: Fulham v Chelsea | E13: 0.25641026 | F13: 0.25641026 | G13: 0.48717949 | H13: 1.034539 | I13: 1.5291909
A14: Team | B14: Struct Attack | C14: Struct Def Weak | D14: GW1 Market xG | E14: GW1 Struct xG | F14: Gap
A15: Arsenal | B15: =VLOOKUP(A15,Team_26_27!$A$2:$U$21,20,FALSE) -> 1.1646206 | C15: =VLOOKUP(A15,Team_26_27!$A$2:$U$21,21,FALSE) -> 0.67296432 | D15: =IFERROR(VLOOKUP(A15,Fixture_Engine!$D$2:$J$21,7,FALSE),"") -> 2.6529358 | E15: =IFERROR(VLOOKUP(A15,Fixture_Engine!$D$2:$H$21,5,FALSE),"") -> 2.249456 | F15: =IF(OR(D15="",E15=""),"",D15-E15) -> 0.40347987
A16: Aston Villa | B16: =VLOOKUP(A16,Team_26_27!$A$2:$U$21,20,FALSE) -> 0.93528526 | C16: =VLOOKUP(A16,Team_26_27!$A$2:$U$21,21,FALSE) -> 1.0103455 | D16: =IFERROR(VLOOKUP(A16,Fixture_Engine!$D$2:$J$21,7,FALSE),"") -> 1.2147039 | E16: =IFERROR(VLOOKUP(A16,Fixture_Engine!$D$2:$H$21,5,FALSE),"") -> 1.1142149 | F16: =IF(OR(D16="",E16=""),"",D16-E16) -> 0.10048904
A17: Bournemouth | B17: =VLOOKUP(A17,Team_26_27!$A$2:$U$21,20,FALSE) -> 1.0910281 | C17: =VLOOKUP(A17,Team_26_27!$A$2:$U$21,21,FALSE) -> 1.0381578 | D17: =IFERROR(VLOOKUP(A17,Fixture_Engine!$D$2:$J$21,7,FALSE),"") -> 0.91917821 | E17: =IFERROR(VLOOKUP(A17,Fixture_Engine!$D$2:$H$21,5,FALSE),"") -> 1.245681 | F17: =IF(OR(D17="",E17=""),"",D17-E17) -> -0.3265028
A18: Brentford | B18: =VLOOKUP(A18,Team_26_27!$A$2:$U$21,20,FALSE) -> 1.0947656 | C18: =VLOOKUP(A18,Team_26_27!$A$2:$U$21,21,FALSE) -> 1.016935 | D18: =IFERROR(VLOOKUP(A18,Fixture_Engine!$D$2:$J$21,7,FALSE),"") -> 1.3720338 | E18: =IFERROR(VLOOKUP(A18,Fixture_Engine!$D$2:$H$21,5,FALSE),"") -> 1.6650091 | F18: =IF(OR(D18="",E18=""),"",D18-E18) -> -0.29297524
A19: Brighton | B19: =VLOOKUP(A19,Team_26_27!$A$2:$U$21,20,FALSE) -> 1.0631331 | C19: =VLOOKUP(A19,Team_26_27!$A$2:$U$21,21,FALSE) -> 0.94708651 | D19: =IFERROR(VLOOKUP(A19,Fixture_Engine!$D$2:$J$21,7,FALSE),"") -> 1.4525482 | E19: =IFERROR(VLOOKUP(A19,Fixture_Engine!$D$2:$H$21,5,FALSE),"") -> 1.6513645 | F19: =IF(OR(D19="",E19=""),"",D19-E19) -> -0.19881629
A20: Chelsea | B20: =VLOOKUP(A20,Team_26_27!$A$2:$U$21,20,FALSE) -> 1.138665 | C20: =VLOOKUP(A20,Team_26_27!$A$2:$U$21,21,FALSE) -> 0.99156076 | D20: =IFERROR(VLOOKUP(A20,Fixture_Engine!$D$2:$J$21,7,FALSE),"") -> 1.5291909 | E20: =IFERROR(VLOOKUP(A20,Fixture_Engine!$D$2:$H$21,5,FALSE),"") -> 1.4365177 | F20: =IF(OR(D20="",E20=""),"",D20-E20) -> 0.092673252
A21: Coventry City | B21: =VLOOKUP(A21,Team_26_27!$A$2:$U$21,20,FALSE) -> 0.78945623 | C21: =VLOOKUP(A21,Team_26_27!$A$2:$U$21,21,FALSE) -> 1.2563413 | D21: =IFERROR(VLOOKUP(A21,Fixture_Engine!$D$2:$J$21,7,FALSE),"") -> 0.52865869 | E21: =IFERROR(VLOOKUP(A21,Fixture_Engine!$D$2:$H$21,5,FALSE),"") -> 0.66827515 | F21: =IF(OR(D21="",E21=""),"",D21-E21) -> -0.13961646
A22: Crystal Palace | B22: =VLOOKUP(A22,Team_26_27!$A$2:$U$21,20,FALSE) -> 1.0527114 | C22: =VLOOKUP(A22,Team_26_27!$A$2:$U$21,21,FALSE) -> 0.98741881 | D22: =IFERROR(VLOOKUP(A22,Fixture_Engine!$D$2:$J$21,7,FALSE),"") -> 1.0054212 | E22: =IFERROR(VLOOKUP(A22,Fixture_Engine!$D$2:$H$21,5,FALSE),"") -> 1.3832447 | F22: =IF(OR(D22="",E22=""),"",D22-E22) -> -0.37782347
A23: Everton | B23: =VLOOKUP(A23,Team_26_27!$A$2:$U$21,20,FALSE) -> 0.91551497 | C23: =VLOOKUP(A23,Team_26_27!$A$2:$U$21,21,FALSE) -> 1.0446108 | D23: =IFERROR(VLOOKUP(A23,Fixture_Engine!$D$2:$J$21,7,FALSE),"") -> 1.3042478 | E23: =IFERROR(VLOOKUP(A23,Fixture_Engine!$D$2:$H$21,5,FALSE),"") -> 1.3897998 | F23: =IF(OR(D23="",E23=""),"",D23-E23) -> -0.085551999
A24: Fulham | B24: =VLOOKUP(A24,Team_26_27!$A$2:$U$21,20,FALSE) -> 0.95122387 | C24: =VLOOKUP(A24,Team_26_27!$A$2:$U$21,21,FALSE) -> 1.0029511 | D24: =IFERROR(VLOOKUP(A24,Fixture_Engine!$D$2:$J$21,7,FALSE),"") -> 1.034539 | E24: =IFERROR(VLOOKUP(A24,Fixture_Engine!$D$2:$H$21,5,FALSE),"") -> 1.450065 | F24: =IF(OR(D24="",E24=""),"",D24-E24) -> -0.41552599
A25: Hull City | B25: =VLOOKUP(A25,Team_26_27!$A$2:$U$21,20,FALSE) -> 0.6979443 | C25: =VLOOKUP(A25,Team_26_27!$A$2:$U$21,21,FALSE) -> 1.3659592 | D25: =IFERROR(VLOOKUP(A25,Fixture_Engine!$D$2:$J$21,7,FALSE),"") -> 0.60545883 | E25: =IFERROR(VLOOKUP(A25,Fixture_Engine!$D$2:$H$21,5,FALSE),"") -> 1.0091683 | F25: =IF(OR(D25="",E25=""),"",D25-E25) -> -0.40370943
A26: Ipswich Town | B26: =VLOOKUP(A26,Team_26_27!$A$2:$U$21,20,FALSE) -> 0.76259947 | C26: =VLOOKUP(A26,Team_26_27!$A$2:$U$21,21,FALSE) -> 1.2336552 | D26: =IFERROR(VLOOKUP(A26,Fixture_Engine!$D$2:$J$21,7,FALSE),"") -> 1.1088257 | E26: =IFERROR(VLOOKUP(A26,Fixture_Engine!$D$2:$H$21,5,FALSE),"") -> 1.1922712 | F26: =IF(OR(D26="",E26=""),"",D26-E26) -> -0.083445563
... A34: Sunderland | B34: =VLOOKUP(A34,Team_26_27!$A$2:$U$21,20,FALSE) -> 0.81270947 | C34: =VLOOKUP(A34,Team_26_27!$A$2:$U$21,21,FALSE) -> 1.016935 | D34: =IFERROR(VLOOKUP(A34,Fixture_Engine!$D$2:$J$21,7,FALSE),"") -> 1.1347602 | E34: =IFERROR(VLOOKUP(A34,Fixture_Engine!$D$2:$H$21,5,FALSE),"") -> 1.261143 | F34: =IF(OR(D34="",E34=""),"",D34-E34) -> -0.12638283
A37: Override architecture: Team_26_27 changes structural channels; Fixture_Engine can override a specific match; GW1_Player can later override minutes.

Sheet Players
A1: Player ID | B1: Code | C1: Player | D1: Full Name | E1: Team | F1: FPL Pos | G1: Start £m | H1: Current £m | I1: Pens Order | J1: Direct FK Order | K1: Corners/IFK Order | L1: Team Join Date | M1: New Club Summer? | N1: Promoted Club? | O1: Manager | P1: Manager Start | Q1: New Manager Summer? | R1: Manager Shift Since Aug-25? | S1: Status | T1: Chance Play GW1 | U1: News | V1: Ownership % | W1: Selectable? | X1: Current Source
A2: 1 | B2: 154561 | C2: Raya | D2: David Raya Martín | E2: Arsenal | F2: GK | G2: 6 | H2: 6 | L2: 2024-07-04 | M2: FALSE | N2: FALSE | O2: Mikel Arteta | P2: 2019-12-22 | Q2: FALSE | R2: FALSE | S2: Available | V2: 0.307 | W2: TRUE | X2: https://fantasy.premierleague.com/
A3: 2 | B3: 109745 | C3: Arrizabalaga | D3: Kepa Arrizabalaga Revuelta | E3: Arsenal | F3: GK | G3: 5 | H3: 5 | L3: 2025-07-01 | M3: FALSE | N3: FALSE | O3: Mikel Arteta | P3: 2019-12-22 | Q3: FALSE | R3: FALSE | S3: Available | V3: 0.002 | W3: TRUE | X3: https://fantasy.premierleague.com/
A4: 3 | B4: 437495 | C4: Meslier | D4: Illan Meslier | E4: Arsenal | F4: GK | G4: 5 | H4: 5 | L4: 2026-07-09 | M4: TRUE | N4: FALSE | O4: Mikel Arteta | P4: 2019-12-22 | Q4: FALSE | R4: FALSE | S4: Available | V4: 0.001 | W4: TRUE | X4: https://fantasy.premierleague.com/
A5: 4 | B5: 226597 | C5: Gabriel | D5: Gabriel dos Santos Magalhães | E5: Arsenal | F5: DEF | G5: 8 | H5: 8 | L5: 2020-09-01 | M5: FALSE | N5: FALSE | O5: Mikel Arteta | P5: 2019-12-22 | Q5: FALSE | R5: FALSE | S5: Available | V5: 0.259 | W5: TRUE | X5: https://fantasy.premierleague.com/
A6: 5 | B6: 445122 | C6: J.Timber | D6: Jurriën Timber | E6: Arsenal | F6: DEF | G6: 6.5 | H6: 6.5 | L6: 2023-07-14 | M6: FALSE | N6: FALSE | O6: Mikel Arteta | P6: 2019-12-22 | Q6: FALSE | R6: FALSE | S6: Injured | T6: 0 | U6: Groin injury - Expected back 21 Aug | V6: 0.005 | W6: TRUE | X6: https://fantasy.premierleague.com/
A7: 6 | B7: 462424 | C7: Saliba | D7: William Saliba | E7: Arsenal | F7: DEF | G7: 6 | H7: 6 | L7: 2019-07-25 | M7: FALSE | N7: FALSE | O7: Mikel Arteta | P7: 2019-12-22 | Q7: FALSE | R7: FALSE | S7: Injured | T7: 0 | U7: Back injury - Unknown return date | V7: 0.005 | W7: TRUE | X7: https://fantasy.premierleague.com/
A8: 7 | B8: 499169 | C8: Lewis-Skelly | D8: Myles Lewis-Skelly | E8: Arsenal | F8: MID | G8: 5.5 | H8: 5.5 | L8: 2022-12-04 | M8: FALSE | N8: FALSE | O8: Mikel Arteta | P8: 2019-12-22 | Q8: FALSE | R8: FALSE | S8: Available | V8: 0.003 | W8: TRUE | X8: https://fantasy.premierleague.com/
A9: 8 | B9: 466075 | C9: Calafiori | D9: Riccardo Calafiori | E9: Arsenal | F9: DEF | G9: 5.5 | H9: 5.5 | L9: 2024-07-29 | M9: FALSE | N9: FALSE | O9: Mikel Arteta | P9: 2019-12-22 | Q9: FALSE | R9: FALSE | S9: Available | V9: 0.153 | W9: TRUE | X9: https://fantasy.premierleague.com/
A10: 9 | B10: 448104 | C10: Hincapie | D10: Piero Hincapié | E10: Arsenal | F10: DEF | G10: 5.5 | H10: 5.5 | L10: 2026-07-01 | M10: TRUE | N10: FALSE | O10: Mikel Arteta | P10: 2019-12-22 | Q10: FALSE | R10: FALSE | S10: Available | V10: 0.044 | W10: TRUE | X10: https://fantasy.premierleague.com/
A11: 10 | B11: 198869 | C11: White | D11: Benjamin White | E11: Arsenal | F11: DEF | G11: 5.5 | H11: 5.5 | L11: 2021-07-30 | M11: FALSE | N11: FALSE | O11: Mikel Arteta | P11: 2019-12-22 | Q11: FALSE | R11: FALSE | S11: Available | T11: 100 | V11: 0.002 | W11: TRUE | X11: https://fantasy.premierleague.com/
A12: 11 | B12: 500040 | C12: Mosquera | D12: Cristhian Mosquera | E12: Arsenal | F12: DEF | G12: 5.5 | H12: 5.5 | L12: 2025-07-24 | M12: FALSE | N12: FALSE | O12: Mikel Arteta | P12: 2019-12-22 | Q12: FALSE | R12: FALSE | S12: Available | V12: 0.169 | W12: TRUE | X12: https://fantasy.premierleague.com/
A13: 12 | B13: 223340 | C13: Saka | D13: Bukayo Saka | E13: Arsenal | F13: MID | G13: 9.5 | H13: 9.5 | I13: 1 | J13: 2 | K13: 6 | L13: 2018-11-28 | M13: FALSE | N13: FALSE | O13: Mikel Arteta | P13: 2019-12-22 | Q13: FALSE | R13: FALSE | S13: Available | V13: 0.106 | W13: TRUE | X13: https://fantasy.premierleague.com/
A14: 13 | B14: 204480 | C14: Rice | D14: Declan Rice | E14: Arsenal | F14: MID | G14: 7.5 | H14: 7.5 | J14: 1 | K14: 5 | L14: 2023-07-15 | M14: FALSE | N14: FALSE | O14: Mikel Arteta | P14: 2019-12-22 | Q14: FALSE | R14: FALSE | S14: Available | V14: 0.223 | W14: TRUE | X14: https://fantasy.premierleague.com/
A15: 14 | B15: 232413 | C15: Eze | D15: Eberechi Eze | E15: Arsenal | F15: MID | G15: 6.5 | H15: 6.5 | J15: 3 | L15: 2025-08-23 | M15: FALSE | N15: FALSE | O15: Mikel Arteta | P15: 2019-12-22 | Q15: FALSE | R15: FALSE | S15: Available | V15: 0.033 | W15: TRUE | X15: https://fantasy.premierleague.com/
A16: 15 | B16: 184029 | C16: Ødegaard | D16: Martin Ødegaard | E16: Arsenal | F16: MID | G16: 6.5 | H16: 6.5 | I16: 3 | K16: 8 | L16: 2021-08-20 | M16: FALSE | N16: FALSE | O16: Mikel Arteta | P16: 2019-12-22 | Q16: FALSE | R16: FALSE | S16: Available | V16: 0.03 | W16: TRUE | X16: https://fantasy.premierleague.com/
A17: 16 | B17: 248857 | C17: Madueke | D17: Noni Madueke | E17: Arsenal | F17: MID | G17: 6.5 | H17: 6.5 | K17: 7 | L17: 2025-07-18 | M17: FALSE | N17: FALSE | O17: Mikel Arteta | P17: 2019-12-22 | Q17: FALSE | R17: FALSE | S17: Available | V17: 0.004 | W17: TRUE | X17: https://fantasy.premierleague.com/
A18: 17 | B18: 195384 | C18: Merino | D18: Mikel Merino Zazón | E18: Arsenal | F18: MID | G18: 6 | H18: 6 | L18: 2024-08-27 | M18: FALSE | N18: FALSE | O18: Mikel Arteta | P18: 2019-12-22 | Q18: FALSE | R18: FALSE | S18: Available | V18: 0.012 | W18: TRUE | X18: https://fantasy.premierleague.com/
A19: 18 | B19: 444145 | C19: Martinelli | D19: Gabriel Martinelli Silva | E19: Arsenal | F19: MID | G19: 6.5 | H19: 6.5 | L19: 2019-07-15 | M19: FALSE | N19: FALSE | O19: Mikel Arteta | P19: 2019-12-22 | Q19: FALSE | R19: FALSE | S19: Available | V19: 0.003 | W19: TRUE | X19: https://fantasy.premierleague.com/
A20: 19 | B20: 481655 | C20: Zubimendi | D20: Martín Zubimendi Ibáñez | E20: Arsenal | F20: MID | G20: 5.5 | H20: 5.5 | L20: 2025-07-06 | M20: FALSE | N20: FALSE | O20: Mikel Arteta | P20: 2019-12-22 | Q20: FALSE | R20: FALSE | S20: Available | V20: 0.015 | W20: TRUE | X20: https://fantasy.premierleague.com/
A21: 20 | B21: 616077 | C21: Dowman | D21: Max Dowman | E21: Arsenal | F21: MID | G21: 5.5 | H21: 5.5 | L21: None | M21: TRUE | N21: FALSE | O21: Mikel Arteta | P21: 2019-12-22 | Q21: FALSE | R21: FALSE | S21: Available | V21: 0.002 | W21: TRUE | X21: https://fantasy.premierleague.com/
A22: 21 | B22: 128295 | C22: Nørgaard | D22: Christian Nørgaard | E22: Arsenal | F22: MID | G22: 5 | H22: 5 | L22: 2025-07-10 | M22: FALSE | N22: FALSE | O22: Mikel Arteta | P22: 2019-12-22 | Q22: FALSE | R22: FALSE | S22: Available | V22: 0.003 | W22: TRUE | X22: https://fantasy.premierleague.com/
A23: 22 | B23: 499175 | C23: Nwaneri | D23: Ethan Nwaneri | E23: Arsenal | F23: MID | G23: 5.5 | H23: 5.5 | L23: 2022-09-17 | M23: FALSE | N23: FALSE | O23: Mikel Arteta | P23: 2019-12-22 | Q23: FALSE | R23: FALSE | S23: Available | V23: 0 | W23: TRUE | X23: https://fantasy.premierleague.com/
A24: 23 | B24: 438098 | C24: Fábio Vieira | D24: Fábio Ferreira Vieira | E24: Arsenal | F24: MID | G24: 5.5 | H24: 5.5 | L24: 2022-06-21 | M24: FALSE | N24: FALSE | O24: Mikel Arteta | P24: 2019-12-22 | Q24: FALSE | R24: FALSE | S24: Available | V24: 0 | W24: TRUE | X24: https://fantasy.premierleague.com/
A25: 24 | B25: 200641 | C25: Nelson | D25: Reiss Nelson | E25: Arsenal | F25: MID | G25: 5.5 | H25: 5.5 | L25: 2017-07-12 | M25: FALSE | N25: FALSE | O25: Mikel Arteta | P25: 2019-12-22 | Q25: FALSE | R25: FALSE | S25: Available | V25: 0 | W25: TRUE | X25: https://fantasy.premierleague.com/
A26: 25 | B26: 224117 | C26: Gyökeres | D26: Viktor Gyökeres | E26: Arsenal | F26: FWD | G26: 7.5 | H26: 7.5 | I26: 2 | L26: 2025-07-26 | M26: FALSE | N26: FALSE | O26: Mikel Arteta | P26: 2019-12-22 | Q26: FALSE | R26: FALSE | S26: Available | V26: 0.13 | W26: TRUE | X26: https://fantasy.premierleague.com/
A27: 26 | B27: 219847 | C27: Havertz | D27: Kai Havertz | E27: Arsenal | F27: FWD | G27: 7.5 | H27: 7.5 | L27: 2023-06-28 | M27: FALSE | N27: FALSE | O27: Mikel Arteta | P27: 2019-12-22 | Q27: FALSE | R27: FALSE | S27: Available | V27: 0.04 | W27: TRUE | X27: https://fantasy.premierleague.com/
A28: 27 | B28: 205651 | C28: G.Jesus | D28: Gabriel Fernando de Jesus | E28: Arsenal | F28: FWD | G28: 6 | H28: 6 | L28: 2022-07-04 | M28: FALSE | N28: FALSE | O28: Mikel Arteta | P28: 2019-12-22 | Q28: FALSE | R28: FALSE | S28: Available | V28: 0.004 | W28: TRUE | X28: https://fantasy.premierleague.com/
A29: 557 | B29: 439509 | C29: Tzolis | D29: Christos Tzolis | E29: Arsenal | F29: MID | G29: 6.5 | H29: 6.5 | L29: 2026-07-23 | M29: TRUE | N29: FALSE | O29: Mikel Arteta | P29: 2019-12-22 | Q29: FALSE | R29: FALSE | S29: Available | V29: 0.017 | W29: TRUE | X29: https://fantasy.premierleague.com/
A30: 28 | B30: 98980 | C30: Martinez | D30: Emiliano Martínez Romero | E30: Aston Villa | F30: GK | G30: 5 | H30: 5 | L30: 2020-09-16 | M30: FALSE | N30: FALSE | O30: Unai Emery | P30: 2022-11-01 | Q30: FALSE | R30: FALSE | S30: Available | V30: 0.046 | W30: TRUE | X30: https://fantasy.premierleague.com/
A31: 29 | B31: 72147 | C31: M.Bizot | D31: Marco Bizot | E31: Aston Villa | F31: GK | G31: 4.5 | H31: 4.5 | L31: 2025-07-15 | M31: FALSE | N31: FALSE | O31: Unai Emery | P31: 2022-11-01 | Q31: FALSE | R31: FALSE | S31: Available | V31: 0.001 | W31: TRUE | X31: https://fantasy.premierleague.com/
A32: 30 | B32: 101188 | C32: Digne | D32: Lucas Digne | E32: Aston Villa | F32: DEF | G32: 4.5 | H32: 4.5 | K32: 4 | L32: 2022-01-13 | M32: FALSE | N32: FALSE | O32: Unai Emery | P32: 2022-11-01 | Q32: FALSE | R32: FALSE | S32: Available | V32: 0.014 | W32: TRUE | X32: https://fantasy.premierleague.com/
A33: 31 | B33: 199798 | C33: Konsa | D33: Ezri Konsa Ngoyo | E33: Aston Villa | F33: DEF | G33: 4.5 | H33: 4.5 | L33: 2019-07-11 | M33: FALSE | N33: FALSE | O33: Unai Emery | P33: 2022-11-01 | Q33: FALSE | R33: FALSE | S33: Available | V33: 0.174 | W33: TRUE | X33: https://fantasy.premierleague.com/
A34: 32 | B34: 199796 | C34: Cash | D34: Matty Cash | E34: Aston Villa | F34: DEF | G34: 4.5 | H34: 4.5 | K34: 5 | L34: 2020-09-03 | M34: FALSE | N34: FALSE | O34: Unai Emery | P34: 2022-11-01 | Q34: FALSE | R34: FALSE | S34: Available | V34: 0.078 | W34: TRUE | X34: https://fantasy.premierleague.com/
A35: 33 | B35: 149484 | C35: Mings | D35: Tyrone Mings | E35: Aston Villa | F35: DEF | G35: 4.5 | H35: 4.5 | L35: 2019-07-08 | M35: FALSE | N35: FALSE | O35: Unai Emery | P35: 2022-11-01 | Q35: FALSE | R35: FALSE | S35: Available | V35: 0.002 | W35: TRUE | X35: https://fantasy.premierleague.com/
A36: 34 | B36: 244954 | C36: Pau | D36: Pau Torres | E36: Aston Villa | F36: DEF | G36: 4.5 | H36: 4.5 | L36: 2023-07-12 | M36: FALSE | N36: FALSE | O36: Unai Emery | P36: 2022-11-01 | Q36: FALSE | R36: FALSE | S36: Available | V36: 0.002 | W36: TRUE | X36: https://fantasy.premierleague.com/
A37: 35 | B37: 515597 | C37: Bogarde | D37: Lamare Bogarde | E37: Aston Villa | F37: MID | G37: 5 | H37: 5 | L37: 2021-01-07 | M37: FALSE | N37: FALSE | O37: Unai Emery | P37: 2022-11-01 | Q37: FALSE | R37: FALSE | S37: Available | V37: 0.001 | W37: TRUE | X37: https://fantasy.premierleague.com/
A38: 36 | B38: 441302 | C38: Maatsen | D38: Ian Maatsen | E38: Aston Villa | F38: DEF | G38: 4.5 | H38: 4.5 | L38: 2024-06-28 | M38: FALSE | N38: FALSE | O38: Unai Emery | P38: 2022-11-01 | Q38: FALSE | R38: FALSE | S38: Available | V38: 0.006 | W38: TRUE | X38: https://fantasy.premierleague.com/
A39: 37 | B39: 184667 | C39: Lindelöf | D39: Victor Lindelöf | E39: Aston Villa | F39: DEF | G39: 4.5 | H39: 4.5 | L39: 2025-09-01 | M39: FALSE | N39: FALSE | O39: Unai Emery | P39: 2022-11-01 | Q39: FALSE | R39: FALSE | S39: Available | V39: 0.002 | W39: TRUE | X39: https://fantasy.premierleague.com/
A40: 38 | B40: 606798 | C40: A.García | D40: Andrés García | E40: Aston Villa | F40: DEF | G40: 4 | H40: 4 | L40: None | M40: TRUE | N40: FALSE | O40: Unai Emery | P40: 2022-11-01 | Q40: FALSE | R40: FALSE | S40: Available | V40: 0.015 | W40: TRUE | X40: https://fantasy.premierleague.com/
...

Sheet Attack_Priors
A1: Player ID | B1: Player | C1: Team | D1: FPL Pos | E1: Hist League | F1: Hist Team | G1: Hist Mins | H1: Hist xG | I1: Hist xA | J1: Hist xG90 | K1: Hist xA90 | L1: Hist Team xG | M1: Hist Team xG/Match | N1: Hist xG Share | O1: Hist xA Share | P1: Base Min Weight | Q1: League Reliability | R1: Team Changed? | S1: Transport Reliability | T1: New Manager Summer? | U1: Manager Reliability | V1: Effective Weight | W1: Pos xG Share Prior | X1: Pos xA Share Prior | Y1: xG Share Prior | Z1: xA Share Prior | AA1: Role xG Share Adj | AB1: Role xA Share Adj | AC1: Current xG Share Prior | AD1: Current xA Share Prior | AE1: Uncertainty | AF1: History Quality | AG1: Pens Order | AH1: Direct FK Order | AI1: Corners/IFK Order | AJ1: Manual Review? | AK1: History Source | AL1: Source URL | AM1: Notes | AN1: Hist Pens Order | AO1: Hist Pens Missed | AP1: Penalty Contamination? | AQ1: npxG Status
A2: 1 | B2: Raya | C2: Arsenal | D2: GK | E2: Premier League | F2: Arsenal | G2: 3330 | H2: 0 | I2: 0.07 | J2: 0 | K2: 0.0018918919 | L2: 65.6 | M2: 1.7263158 | N2: 0 | O2: 0.001095913 | P2: =IFERROR(G2/(G2+Priors!$H$3),0) -> 0.76905312 | Q2: =IF(E2="Premier League",Priors!$H$4,IF(E2="Championship",Priors!$H$5,Priors!$H$8)) -> 1 | R2: FALSE | S2: =IF(R2=TRUE,Priors!$H$6,1) -> 1 | T2: FALSE | U2: =IF(T2=TRUE,Priors!$H$7,1) -> 1 | V2: =P2*Q2*S2*U2 -> 0.76905312 | W2: =VLOOKUP(D2,Priors!$A$3:$C$6,2,FALSE) -> 0.00016719535 | X2: =VLOOKUP(D2,Priors!$A$3:$C$6,3,FALSE) -> 0.0013793616 | Y2: =IF(N2="",W2,V2*N2+(1-V2)*W2) -> 3.8613245e-05 | Z2: =IF(O2="",X2,V2*O2+(1-V2)*X2) -> 0.0011613746 | AA2: 1 | AB2: 1 | AC2: =Y2*AA2 -> 3.8613245e-05 | AD2: =Z2*AB2 -> 0.0011613746 | AE2: =1-V2 -> 0.23094688 | AF2: PL history | AJ2: FALSE | AK2: FPL Core Insights / official FPL historical feed | AL2: https://github.com/olbauday/FPL-Core-Insights/tree/main/data/2025-2026 | AO2: 0 | AP2: FALSE | AQ2: Total xG retained; low penalty contamination
A3: 2 | B3: Arrizabalaga | C3: Arsenal | D3: GK | E3: Premier League | F3: Arsenal | G3: 90 | H3: 0 | I3: 0 | J3: 0 | K3: 0 | L3: 65.6 | M3: 1.7263158 | N3: 0 | O3: 0 | P3: =IFERROR(G3/(G3+Priors!$H$3),0) -> 0.082568807 | Q3: =IF(E3="Premier League",Priors!$H$4,IF(E3="Championship",Priors!$H$5,Priors!$H$8)) -> 1 | R3: FALSE | S3: =IF(R3=TRUE,Priors!$H$6,1) -> 1 | T3: FALSE | U3: =IF(T3=TRUE,Priors!$H$7,1) -> 1 | V3: =P3*Q3*S3*U3 -> 0.082568807 | W3: =VLOOKUP(D3,Priors!$A$3:$C$6,2,FALSE) -> 0.00016719535 | X3: =VLOOKUP(D3,Priors!$A$3:$C$6,3,FALSE) -> 0.0013793616 | Y3: =IF(N3="",W3,V3*N3+(1-V3)*W3) -> 0.00015339023 | Z3: =IF(O3="",X3,V3*O3+(1-V3)*X3) -> 0.0012654694 | AA3: 1 | AB3: 1 | AC3: =Y3*AA3 -> 0.00015339023 | AD3: =Z3*AB3 -> 0.0012654694 | AE3: =1-V3 -> 0.91743119 | AF3: PL history | AJ3: TRUE | AK3: FPL Core Insights / official FPL historical feed | AL3: https://github.com/olbauday/FPL-Core-Insights/tree/main/data/2025-2026 | AO3: 0 | AP3: FALSE | AQ3: Total xG retained; low penalty contamination
A4: 3 | B4: Meslier | C4: Arsenal | D4: GK | E4: Missing/non-PL | P4: =IFERROR(G4/(G4+Priors!$H$3),0) -> 0 | Q4: =IF(E4="Premier League",Priors!$H$4,IF(E4="Championship",Priors!$H$5,Priors!$H$8)) -> 0 | R4: FALSE | S4: =IF(R4=TRUE,Priors!$H$6,1) -> 1 | T4: FALSE | U4: =IF(T4=TRUE,Priors!$H$7,1) -> 1 | V4: =P4*Q4*S4*U4 -> 0 | W4: =VLOOKUP(D4,Priors!$A$3:$C$6,2,FALSE) -> 0.00016719535 | X4: =VLOOKUP(D4,Priors!$A$3:$C$6,3,FALSE) -> 0.0013793616 | Y4: =IF(N4="",W4,V4*N4+(1-V4)*W4) -> 0.00016719535 | Z4: =IF(O4="",X4,V4*O4+(1-V4)*X4) -> 0.0013793616 | AA4: 1 | AB4: 1 | AC4: =Y4*AA4 -> 0.00016719535 | AD4: =Z4*AB4 -> 0.0013793616 | AE4: =1-V4 -> 1 | AF4: Missing/non-PL | AJ4: TRUE | AK4: No reliable 25/26 history loaded | AO4: 0 | AP4: FALSE | AQ4: Total xG retained; low penalty contamination
A5: 4 | B5: Gabriel | C5: Arsenal | D5: DEF | E5: Premier League | F5: Arsenal | G5: 2750 | H5: 2.94 | I5: 1.75 | J5: 0.096218182 | K5: 0.057272727 | L5: 65.6 | M5: 1.7263158 | N5: 0.055736142 | O5: 0.033176275 | P5: =IFERROR(G5/(G5+Priors!$H$3),0) -> 0.73333333 | Q5: =IF(E5="Premier League",Priors!$H$4,IF(E5="Championship",Priors!$H$5,Priors!$H$8)) -> 1 | R5: FALSE | S5: =IF(R5=TRUE,Priors!$H$6,1) -> 1 | T5: FALSE | U5: =IF(T5=TRUE,Priors!$H$7,1) -> 1 | V5: =P5*Q5*S5*U5 -> 0.73333333 | W5: =VLOOKUP(D5,Priors!$A$3:$C$6,2,FALSE) -> 0.041142361 | X5: =VLOOKUP(D5,Priors!$A$3:$C$6,3,FALSE) -> 0.04051308 | Y5: =IF(N5="",W5,V5*N5+(1-V5)*W5) -> 0.051844467 | Z5: =IF(O5="",X5,V5*O5+(1-V5)*X5) -> 0.035132756 | AA5: 1 | AB5: 1 | AC5: =Y5*AA5 -> 0.051844467 | AD5: =Z5*AB5 -> 0.035132756 | AE5: =1-V5 -> 0.26666667 | AF5: PL history | AJ5: FALSE | AK5: FPL Core Insights / official FPL historical feed | AL5: https://github.com/olbauday/FPL-Core-Insights/tree/main/data/2025-2026 | AO5: 0 | AP5: FALSE | AQ5: Total xG retained; low penalty contamination
A6: 5 | B6: J.Timber | C6: Arsenal | D6: DEF | E6: Premier League | F6: Arsenal | G6: 2452 | H6: 4.71 | I6: 1.53 | J6: 0.17287928 | K6: 0.056158238 | L6: 65.6 | M6: 1.7263158 | N6: 0.10014349 | O6: 0.032530687 | P6: =IFERROR(G6/(G6+Priors!$H$3),0) -> 0.71031286 | Q6: =IF(E6="Premier League",Priors!$H$4,IF(E6="Championship",Priors!$H$5,Priors!$H$8)) -> 1 | R6: FALSE | S6: =IF(R6=TRUE,Priors!$H$6,1) -> 1 | T6: FALSE | U6: =IF(T6=TRUE,Priors!$H$7,1) -> 1 | V6: =P6*Q6*S6*U6 -> 0.71031286 | W6: =VLOOKUP(D6,Priors!$A$3:$C$6,2,FALSE) -> 0.041142361 | X6: =VLOOKUP(D6,Priors!$A$3:$C$6,3,FALSE) -> 0.04051308 | Y6: =IF(N6="",W6,V6*N6+(1-V6)*W6) -> 0.08305162 | Z6: =IF(O6="",X6,V6*O6+(1-V6)*X6) -> 0.034843083 | AA6: 1 | AB6: 1 | AC6: =Y6*AA6 -> 0.08305162 | AD6: =Z6*AB6 -> 0.034843083 | AE6: =1-V6 -> 0.28968714 | AF6: PL history | AJ6: FALSE | AK6: FPL Core Insights / official FPL historical feed | AL6: https://github.com/olbauday/FPL-Core-Insights/tree/main/data/2025-2026 | AO6: 0 | AP6: FALSE | AQ6: Total xG retained; low penalty contamination
A7: 6 | B7: Saliba | C7: Arsenal | D7: DEF | E7: Premier League | F7: Arsenal | G7: 2614 | H7: 0.88 | I7: 1.21 | J7: 0.030298393 | K7: 0.041660291 | L7: 65.6 | M7: 1.7263158 | N7: 0.017550899 | O7: 0.024132485 | P7: =IFERROR(G7/(G7+Priors!$H$3),0) -> 0.72329828 | Q7: =IF(E7="Premier League",Priors!$H$4,IF(E7="Championship",Priors!$H$5,Priors!$H$8)) -> 1 | R7: FALSE | S7: =IF(R7=TRUE,Priors!$H$6,1) -> 1 | T7: FALSE | U7: =IF(T7=TRUE,Priors!$H$7,1) -> 1 | V7: =P7*Q7*S7*U7 -> 0.72329828 | W7: =VLOOKUP(D7,Priors!$A$3:$C$6,2,FALSE) -> 0.041142361 | X7: =VLOOKUP(D7,Priors!$A$3:$C$6,3,FALSE) -> 0.04051308 | Y7: =IF(N7="",W7,V7*N7+(1-V7)*W7) -> 0.024078697 | Z7: =IF(O7="",X7,V7*O7+(1-V7)*X7) -> 0.028665024 | AA7: 1 | AB7: 1 | AC7: =Y7*AA7 -> 0.024078697 | AD7: =Z7*AB7 -> 0.028665024 | AE7: =1-V7 -> 0.27670172 | AF7: PL history | AJ7: FALSE | AK7: FPL Core Insights / official FPL historical feed | AL7: https://github.com/olbauday/FPL-Core-Insights/tree/main/data/2025-2026 | AO7: 0 | AP7: FALSE | AQ7: Total xG retained; low penalty contamination
A8: 7 | B8: Lewis-Skelly | C8: Arsenal | D8: MID | E8: Premier League | F8: Arsenal | G8: 697 | H8: 0.1 | I8: 0.2 | J8: 0.012912482 | K8: 0.025824964 | L8: 65.6 | M8: 1.7263158 | N8: 0.0074797914 | O8: 0.014959583 | P8: =IFERROR(G8/(G8+Priors!$H$3),0) -> 0.41072481 | Q8: =IF(E8="Premier League",Priors!$H$4,IF(E8="Championship",Priors!$H$5,Priors!$H$8)) -> 1 | R8: FALSE | S8: =IF(R8=TRUE,Priors!$H$6,1) -> 1 | T8: FALSE | U8: =IF(T8=TRUE,Priors!$H$7,1) -> 1 | V8: =P8*Q8*S8*U8 -> 0.41072481 | W8: =VLOOKUP(D8,Priors!$A$3:$C$6,2,FALSE) -> 0.10751786 | X8: =VLOOKUP(D8,Priors!$A$3:$C$6,3,FALSE) -> 0.090240672 | Y8: =IF(N8="",W8,V8*N8+(1-V8)*W8) -> 0.066429744 | Z8: =IF(O8="",X8,V8*O8+(1-V8)*X8) -> 0.059320861 | AA8: 1 | AB8: 1 | AC8: =Y8*AA8 -> 0.066429744 | AD8: =Z8*AB8 -> 0.059320861 | AE8: =1-V8 -> 0.58927519 | AF8: PL history | AJ8: TRUE | AK8: FPL Core Insights / official FPL historical feed | AL8: https://github.com/olbauday/FPL-Core-Insights/tree/main/data/2025-2026 | AO8: 0 | AP8: FALSE | AQ8: Total xG retained; low penalty contamination
A9: 8 | B9: Calafiori | C9: Arsenal | D9: DEF | E9: Premier League | F9: Arsenal | G9: 1697 | H9: 3.36 | I9: 0.76 | J9: 0.17819682 | K9: 0.040306423 | L9: 65.6 | M9: 1.7263158 | N9: 0.10322377 | O9: 0.023348233 | P9: =IFERROR(G9/(G9+Priors!$H$3),0) -> 0.62921765 | Q9: =IF(E9="Premier League",Priors!$H$4,IF(E9="Championship",Priors!$H$5,Priors!$H$8)) -> 1 | R9: FALSE | S9: =IF(R9=TRUE,Priors!$H$6,1) -> 1 | T9: FALSE | U9: =IF(T9=TRUE,Priors!$H$7,1) -> 1 | V9: =P9*Q9*S9*U9 -> 0.62921765 | W9: =VLOOKUP(D9,Priors!$A$3:$C$6,2,FALSE) -> 0.041142361 | X9: =VLOOKUP(D9,Priors!$A$3:$C$6,3,FALSE) -> 0.04051308 | Y9: =IF(N9="",W9,V9*N9+(1-V9)*W9) -> 0.080205077 | Z9: =IF(O9="",X9,V9*O9+(1-V9)*X9) -> 0.029712655 | AA9: 1 | AB9: 1 | AC9: =Y9*AA9 -> 0.080205077 | AD9: =Z9*AB9 -> 0.029712655 | AE9: =1-V9 -> 0.37078235 | AF9: PL history | AJ9: FALSE | AK9: FPL Core Insights / official FPL historical feed | AL9: https://github.com/olbauday/FPL-Core-Insights/tree/main/data/2025-2026 | AO9: 0 | AP9: FALSE | AQ9: Total xG retained; low penalty contamination
A10: 9 | B10: Hincapie | C10: Arsenal | D10: DEF | E10: Premier League | F10: Arsenal | G10: 1787 | H10: 0.36 | I10: 1.67 | J10: 0.018130946 | K10: 0.084107443 | L10: 65.6 | M10: 1.7263158 | N10: 0.010502682 | O10: 0.048720775 | P10: =IFERROR(G10/(G10+Priors!$H$3),0) -> 0.64119125 | Q10: =IF(E10="Premier League",Priors!$H$4,IF(E10="Championship",Priors!$H$5,Priors!$H$8)) -> 1 | R10: FALSE | S10: =IF(R10=TRUE,Priors!$H$6,1) -> 1 | T10: FALSE | U10: =IF(T10=TRUE,Priors!$H$7,1) -> 1 | V10: =P10*Q10*S10*U10 -> 0.64119125 | W10: =VLOOKUP(D10,Priors!$A$3:$C$6,2,FALSE) -> 0.041142361 | X10: =VLOOKUP(D10,Priors!$A$3:$C$6,3,FALSE) -> 0.04051308 | Y10: =IF(N10="",W10,V10*N10+(1-V10)*W10) -> 0.021496467 | Z10: =IF(O10="",X10,V10*O10+(1-V10)*X10) -> 0.045775782 | AA10: 1 | AB10: 1 | AC10: =Y10*AA10 -> 0.021496467 | AD10: =Z10*AB10 -> 0.045775782 | AE10: =1-V10 -> 0.35880875 | AF10: PL history | AJ10: FALSE | AK10: FPL Core Insights / official FPL historical feed | AL10: https://github.com/olbauday/FPL-Core-Insights/tree/main/data/2025-2026 | AO10: 0 | AP10: FALSE | AQ10: Total xG retained; low penalty contamination
A11: 10 | B11: White | C11: Arsenal | D11: DEF | E11: Premier League | F11: Arsenal | G11: 699 | H11: 0.45 | I11: 0.69 | J11: 0.057939914 | K11: 0.088841202 | L11: 65.6 | M11: 1.7263158 | N11: 0.033562755 | O11: 0.051462891 | P11: =IFERROR(G11/(G11+Priors!$H$3),0) -> 0.41141848 | Q11: =IF(E11="Premier League",Priors!$H$4,IF(E11="Championship",Priors!$H$5,Priors!$H$8)) -> 1 | R11: FALSE | S11: =IF(R11=TRUE,Priors!$H$6,1) -> 1 | T11: FALSE | U11: =IF(T11=TRUE,Priors!$H$7,1) -> 1 | V11: =P11*Q11*S11*U11 -> 0.41141848 | W11: =VLOOKUP(D11,Priors!$A$3:$C$6,2,FALSE) -> 0.041142361 | X11: =VLOOKUP(D11,Priors!$A$3:$C$6,3,FALSE) -> 0.04051308 | Y11: =IF(N11="",W11,V11*N11+(1-V11)*W11) -> 0.038023971 | Z11: =IF(O11="",X11,V11*O11+(1-V11)*X11) -> 0.045018035 | AA11: 1 | AB11: 1 | AC11: =Y11*AA11 -> 0.038023971 | AD11: =Z11*AB11 -> 0.045018035 | AE11: =1-V11 -> 0.58858152 | AF11: PL history | AJ11: TRUE | AK11: FPL Core Insights / official FPL historical feed | AL11: https://github.com/olbauday/FPL-Core-Insights/tree/main/data/2025-2026 | AO11: 0 | AP11: FALSE | AQ11: Total xG retained; low penalty contamination
A12: 11 | B12: Mosquera | C12: Arsenal | D12: DEF | E12: Premier League | F12: Arsenal | G12: 986 | H12: 0.1 | I12: 0.63 | J12: 0.009127789 | K12: 0.057505071 | L12: 65.6 | M12: 1.7263158 | N12: 0.0052874388 | O12: 0.033310864 | P12: =IFERROR(G12/(G12+Priors!$H$3),0) -> 0.49647533 | Q12: =IF(E12="Premier League",Priors!$H$4,IF(E12="Championship",Priors!$H$5,Priors!$H$8)) -> 1 | R12: FALSE | S12: =IF(R12=TRUE,Priors!$H$6,1) -> 1 | T12: FALSE | U12: =IF(T12=TRUE,Priors!$H$7,1) -> 1 | V12: =P12*Q12*S12*U12 -> 0.49647533 | W12: =VLOOKUP(D12,Priors!$A$3:$C$6,2,FALSE) -> 0.041142361 | X12: =VLOOKUP(D12,Priors!$A$3:$C$6,3,FALSE) -> 0.04051308 | Y12: =IF(N12="",W12,V12*N12+(1-V12)*W12) -> 0.023341277 | Z12: =IF(O12="",X12,V12*O12+(1-V12)*X12) -> 0.036937358 | AA12: 1 | AB12: 1 | AC12: =Y12*AA12 -> 0.023341277 | AD12: =Z12*AB12 -> 0.036937358 | AE12: =1-V12 -> 0.50352467 | AF12: PL history | AJ12: FALSE | AK12: FPL Core Insights / official FPL historical feed | AL12: https://github.com/olbauday/FPL-Core-Insights/tree/main/data/2025-2026 | AO12: 0 | AP12: FALSE | AQ12: Total xG retained; low penalty contamination
A13: 12 | B13: Saka | C13: Arsenal | D13: MID | E13: Premier League | F13: Arsenal | G13: 2218 | H13: 7.57 | I13: 7.16 | J13: 0.30716862 | K13: 0.29053201 | L13: 65.6 | M13: 1.7263158 | N13: 0.17793304 | O13: 0.16829598 | P13: =IFERROR(G13/(G13+Priors!$H$3),0) -> 0.68924798 | Q13: =IF(E13="Premier League",Priors!$H$4,IF(E13="Championship",Priors!$H$5,Priors!$H$8)) -> 1 | R13: FALSE | S13: =IF(R13=TRUE,Priors!$H$6,1) -> 1 | T13: FALSE | U13: =IF(T13=TRUE,Priors!$H$7,1) -> 1 | V13: =P13*Q13*S13*U13 -> 0.68924798 | W13: =VLOOKUP(D13,Priors!$A$3:$C$6,2,FALSE) -> 0.10751786 | X13: =VLOOKUP(D13,Priors!$A$3:$C$6,3,FALSE) -> 0.090240672 | Y13: =IF(N13="",W13,V13*N13+(1-V13)*W13) -> 0.15605138 | Z13: =IF(O13="",X13,V13*O13+(1-V13)*X13) -> 0.14404014 | AA13: 1 | AB13: 1 | AC13: =Y13*AA13 -> 0.15605138 | AD13: =Z13*AB13 -> 0.14404014 | AE13: =1-V13 -> 0.31075202 | AF13: PL history | AG13: 1 | AH13: 2 | AI13: 6 | AJ13: FALSE | AK13: FPL Core Insights / official FPL historical feed | AL13: https://github.com/olbauday/FPL-Core-Insights/tree/main/data/2025-2026 | AN13: 1 | AO13: 0 | AP13: TRUE | AQ13: Total xG retained; penalty channel not decomposed
A14: 13 | B14: Rice | C14: Arsenal | D14: MID | E14: Premier League | F14: Arsenal | G14: 3093 | H14: 3.15 | I14: 7.32 | J14: 0.091658584 | K14: 0.21299709 | L14: 65.6 | M14: 1.7263158 | N14: 0.053094911 | O14: 0.12338246 | P14: =IFERROR(G14/(G14+Priors!$H$3),0) -> 0.75568043 | Q14: =IF(E14="Premier League",Priors!$H$4,IF(E14="Championship",Priors!$H$5,Priors!$H$8)) -> 1 | R14: FALSE | S14: =IF(R14=TRUE,Priors!$H$6,1) -> 1 | T14: FALSE | U14: =IF(T14=TRUE,Priors!$H$7,1) -> 1 | V14: =P14*Q14*S14*U14 -> 0.75568043 | W14: =VLOOKUP(D14,Priors!$A$3:$C$6,2,FALSE) -> 0.10751786 | X14: =VLOOKUP(D14,Priors!$A$3:$C$6,3,FALSE) -> 0.090240672 | Y14: =IF(N14="",W14,V14*N14+(1-V14)*W14) -> 0.066391503 | Z14: =IF(O14="",X14,V14*O14+(1-V14)*X14) -> 0.11528527 | AA14: 1 | AB14: 1 | AC14: =Y14*AA14 -> 0.066391503 | AD14: =Z14*AB14 -> 0.11528527 | AE14: =1-V14 -> 0.24431957 | AF14: PL history | AH14: 1 | AI14: 5 | AJ14: FALSE | AK14: FPL Core Insights / official FPL historical feed | AL14: https://github.com/olbauday/FPL-Core-Insights/tree/main/data/2025-2026 | AO14: 0 | AP14: FALSE | AQ14: Total xG retained; low penalty contamination
A15: 14 | B15: Eze | C15: Arsenal | D15: MID | E15: Premier League | F15: Arsenal | G15: 1885 | H15: 5.18 | I15: 2.66 | J15: 0.24732095 | K15: 0.12700265 | L15: 65.6 | M15: 1.7263158 | N15: 0.14326519 | O15: 0.07356861 | P15: =IFERROR(G15/(G15+Priors!$H$3),0) -> 0.65337955 | Q15: =IF(E15="Premier League",Priors!$H$4,IF(E15="Championship",Priors!$H$5,Priors!$H$8)) -> 1 | R15: FALSE | S15: =IF(R15=TRUE,Priors!$H$6,1) -> 1 | T15: FALSE | U15: =IF(T15=TRUE,Priors!$H$7,1) -> 1 | V15: =P15*Q15*S15*U15 -> 0.65337955 | W15: =VLOOKUP(D15,Priors!$A$3:$C$6,2,FALSE) -> 0.10751786 | X15: =VLOOKUP(D15,Priors!$A$3:$C$6,3,FALSE) -> 0.090240672 | Y15: =IF(N15="",W15,V15*N15+(1-V15)*W15) -> 0.13087443 | Z15: =IF(O15="",X15,V15*O15+(1-V15)*X15) -> 0.079347487 | AA15: 1 | AB15: 1 | AC15: =Y15*AA15 -> 0.13087443 | AD15: =Z15*AB15 -> 0.079347487 | AE15: =1-V15 -> 0.34662045 | AF15: PL history | AH15: 3 | AJ15: FALSE | AK15: FPL Core Insights / official FPL historical feed | AL15: https://github.com/olbauday/FPL-Core-Insights/tree/main/data/2025-2026 | AO15: 0 | AP15: FALSE | AQ15: Total xG retained; low penalty contamination
A16: 15 | B16: Ødegaard | C16: Arsenal | D16: MID | E16: Premier League | F16: Arsenal | G16: 1363 | H16: 1.25 | I16: 3.65 | J16: 0.082538518 | K16: 0.24101247 | L16: 65.6 | M16: 1.7263158 | N16: 0.047811946 | O16: 0.13961088 | P16: =IFERROR(G16/(G16+Priors!$H$3),0) -> 0.57680914 | Q16: =IF(E16="Premier League",Priors!$H$4,IF(E16="Championship",Priors!$H$5,Priors!$H$8)) -> 1 | R16: FALSE | S16: =IF(R16=TRUE,Priors!$H$6,1) -> 1 | T16: FALSE | U16: =IF(T16=TRUE,Priors!$H$7,1) -> 1 | V16: =P16*Q16*S16*U16 -> 0.57680914 | W16: =VLOOKUP(D16,Priors!$A$3:$C$6,2,FALSE) -> 0.10751786 | X16: =VLOOKUP(D16,Priors!$A$3:$C$6,3,FALSE) -> 0.090240672 | Y16: =IF(N16="",W16,V16*N16+(1-V16)*W16) -> 0.073078944 | Z16: =IF(O16="",X16,V16*O16+(1-V16)*X16) -> 0.11871786 | AA16: 1 | AB16: 1 | AC16: =Y16*AA16 -> 0.073078944 | AD16: =Z16*AB16 -> 0.11871786 | AE16: =1-V16 -> 0.42319086 | AF16: PL history | AG16: 3 | AI16: 8 | AJ16: FALSE | AK16: FPL Core Insights / official FPL historical feed | AL16: https://github.com/olbauday/FPL-Core-Insights/tree/main/data/2025-2026 | AN16: 3 | AO16: 0 | AP16: FALSE | AQ16: Total xG retained; low penalty contamination
A17: 16 | B17: Madueke | C17: Arsenal | D17: MID | E17: Premier League | F17: Arsenal | G17: 1205 | H17: 1.23 | I17: 2.86 | J17: 0.09186722 | K17: 0.21360996 | L17: 65.6 | M17: 1.7263158 | N17: 0.053215768 | O17: 0.12373748 | P17: =IFERROR(G17/(G17+Priors!$H$3),0) -> 0.54648526 | Q17: =IF(E17="Premier League",Priors!$H$4,IF(E17="Championship",Priors!$H$5,Priors!$H$8)) -> 1 | R17: FALSE | S17: =IF(R17=TRUE,Priors!$H$6,1) -> 1 | T17: FALSE | U17: =IF(T17=TRUE,Priors!$H$7,1) -> 1 | V17: =P17*Q17*S17*U17 -> 0.54648526 | W17: =VLOOKUP(D17,Priors!$A$3:$C$6,2,FALSE) -> 0.10751786 | X17: =VLOOKUP(D17,Priors!$A$3:$C$6,3,FALSE) -> 0.090240672 | Y17: =IF(N17="",W17,V17*N17+(1-V17)*W17) -> 0.077842567 | Z17: =IF(O17="",X17,V17*O17+(1-V17)*X17) -> 0.10854618 | AA17: 1 | AB17: 1 | AC17: =Y17*AA17 -> 0.077842567 | AD17: =Z17*AB17 -> 0.10854618 | AE17: =1-V17 -> 0.45351474 | AF17: PL history | AI17: 7 | AJ17: FALSE | AK17: FPL Core Insights / official FPL historical feed | AL17: https://github.com/olbauday/FPL-Core-Insights/tree/main/data/2025-2026 | AO17: 0 | AP17: FALSE | AQ17: Total xG retained; low penalty contamination
A18: 17 | B18: Merino | C18: Arsenal | D18: MID | E18: Premier League | F18: Arsenal | G18: 1024 | H18: 3.36 | I18: 1.45 | J18: 0.2953125 | K18: 0.12744141 | L18: 65.6 | M18: 1.7263158 | N18: 0.17106517 | O18: 0.073822766 | P18: =IFERROR(G18/(G18+Priors!$H$3),0) -> 0.50592885 | Q18: =IF(E18="Premier League",Priors!$H$4,IF(E18="Championship",Priors!$H$5,Priors!$H$8)) -> 1 | R18: FALSE | S18: =IF(R18=TRUE,Priors!$H$6,1) -> 1 | T18: FALSE | U18: =IF(T18=TRUE,Priors!$H$7,1) -> 1 | V18: =P18*Q18*S18*U18 -> 0.50592885 | W18: =VLOOKUP(D18,Priors!$A$3:$C$6,2,FALSE) -> 0.10751786 | X18: =VLOOKUP(D18,Priors!$A$3:$C$6,3,FALSE) -> 0.090240672 | Y18: =IF(N18="",W18,V18*N18+(1-V18)*W18) -> 0.13966828 | Z18: =IF(O18="",X18,V18*O18+(1-V18)*X18) -> 0.08193438 | AA18: 1 | AB18: 1 | AC18: =Y18*AA18 -> 0.13966828 | AD18: =Z18*AB18 -> 0.08193438 | AE18: =1-V18 -> 0.49407115 | AF18: PL history | AJ18: FALSE | AK18: FPL Core Insights / official FPL historical feed | AL18: https://github.com/olbauday/FPL-Core-Insights/tree/main/data/2025-2026 | AO18: 0 | AP18: FALSE | AQ18: Total xG retained; low penalty contamination
A19: 18 | B19: Martinelli | C19: Arsenal | D19: MID | E19: Premier League | F19: Arsenal | G19: 1065 | H19: 4.12 | I19: 1.27 | J19: 0.34816901 | K19: 0.10732394 | L19: 65.6 | M19: 1.7263158 | N19: 0.20168327 | O19: 0.062169358 | P19: =IFERROR(G19/(G19+Priors!$H$3),0) -> 0.5157385 | Q19: =IF(E19="Premier League",Priors!$H$4,IF(E19="Championship",Priors!$H$5,Priors!$H$8)) -> 1 | R19: FALSE | S19: =IF(R19=TRUE,Priors!$H$6,1) -> 1 | T19: FALSE | U19: =IF(T19=TRUE,Priors!$H$7,1) -> 1 | V19: =P19*Q19*S19*U19 -> 0.5157385 | W19: =VLOOKUP(D19,Priors!$A$3:$C$6,2,FALSE) -> 0.10751786 | X19: =VLOOKUP(D19,Priors!$A$3:$C$6,3,FALSE) -> 0.090240672 | Y19: =IF(N19="",W19,V19*N19+(1-V19)*W19) -> 0.15608259 | Z19: =IF(O19="",X19,V19*O19+(1-V19)*X19) -> 0.075763214 | AA19: 1 | AB19: 1 | AC19: =Y19*AA19 -> 0.15608259 | AD19: =Z19*AB19 -> 0.075763214 | AE19: =1-V19 -> 0.4842615 | AF19: PL history | AJ19: FALSE | AK19: FPL Core Insights / official FPL historical feed | AL19: https://github.com/olbauday/FPL-Core-Insights/tree/main/data/2025-2026 | AO19: 0 | AP19: FALSE | AQ19: Total xG retained; low penalty contamination
A20: 19 | B20: Zubimendi | C20: Arsenal | D20: MID | E20: Premier League | F20: Arsenal | G20: 2991 | H20: 2.84 | I20: 2.27 | J20: 0.085456369 | K20: 0.068304915 | L20: 65.6 | M20: 1.7263158 | N20: 0.049502165 | O20: 0.039566871 | P20: =IFERROR(G20/(G20+Priors!$H$3),0) -> 0.74943623 | Q20: =IF(E20="Premier League",Priors!$H$4,IF(E20="Championship",Priors!$H$5,Priors!$H$8)) -> 1 | R20: FALSE | S20: =IF(R20=TRUE,Priors!$H$6,1) -> 1 | T20: FALSE | U20: =IF(T20=TRUE,Priors!$H$7,1) -> 1 | V20: =P20*Q20*S20*U20 -> 0.74943623 | W20: =VLOOKUP(D20,Priors!$A$3:$C$6,2,FALSE) -> 0.10751786 | X20: =VLOOKUP(D20,Priors!$A$3:$C$6,3,FALSE) -> 0.090240672 | Y20: =IF(N20="",W20,V20*N20+(1-V20)*W20) -> 0.064038796 | Z20: =IF(O20="",X20,V20*O20+(1-V20)*X20) -> 0.05226389 | AA20: 1 | AB20: 1 | AC20: =Y20*AA20 -> 0.064038796 | AD20: =Z20*AB20 -> 0.05226389 | AE20: =1-V20 -> 0.25056377 | AF20: PL history | AJ20: FALSE | AK20: FPL Core Insights / official FPL historical feed | AL20: https://github.com/olbauday/FPL-Core-Insights/tree/main/data/2025-2026 | AO20: 0 | AP20: FALSE | AQ20: Total xG retained; low penalty contamination
A21: 20 | B21: Dowman | C21: Arsenal | D21: MID | E21: Premier League | F21: Arsenal | G21: 152 | H21: 1.19 | I21: 0.3 | J21: 0.70460526 | K21: 0.17763158 | L21: 65.6 | M21: 1.7263158 | N21: 0.40815549 | O21: 0.10289634 | P21: =IFERROR(G21/(G21+Priors!$H$3),0) -> 0.13194444 | Q21: =IF(E21="Premier League",Priors!$H$4,IF(E21="Championship",Priors!$H$5,Priors!$H$8)) -> 1 | R21: FALSE | S21: =IF(R21=TRUE,Priors!$H$6,1) -> 1 | T21: FALSE | U21: =IF(T21=TRUE,Priors!$H$7,1) -> 1 | V21: =P21*Q21*S21*U21 -> 0.13194444 | W21: =VLOOKUP(D21,Priors!$A$3:$C$6,2,FALSE) -> 0.10751786 | X21: =VLOOKUP(D21,Priors!$A$3:$C$6,3,FALSE) -> 0.090240672 | Y21: =IF(N21="",W21,V21*N21+(1-V21)*W21) -> 0.14718533 | Z21: =IF(O21="",X21,V21*O21+(1-V21)*X21) -> 0.091910517 | AA21: 1 | AB21: 1 | AC21: =Y21*AA21 -> 0.14718533 | AD21: =Z21*AB21 -> 0.091910517 | AE21: =1-V21 -> 0.86805556 | AF21: PL history | AJ21: TRUE | AK21: FPL Core Insights / official FPL historical feed | AL21: https://github.com/olbauday/FPL-Core-Insights/tree/main/data/2025-2026 | AO21: 0 | AP21: FALSE | AQ21: Total xG retained; low penalty contamination
A22: 21 | B22: Nørgaard | C22: Arsenal | D22: MID | E22: Premier League | F22: Arsenal | G22: 101 | H22: 0.08 | I22: 0.04 | J22: 0.071287129 | K22: 0.035643564 | L22: 65.6 | M22: 1.7263158 | N22: 0.041294373 | O22: 0.020647187 | P22: =IFERROR(G22/(G22+Priors!$H$3),0) -> 0.091734787 | Q22: =IF(E22="Premier League",Priors!$H$4,IF(E22="Championship",Priors!$H$5,Priors!$H$8)) -> 1 | R22: FALSE | S22: =IF(R22=TRUE,Priors!$H$6,1) -> 1 | T22: FALSE | U22: =IF(T22=TRUE,Priors!$H$7,1) -> 1 | V22: =P22*Q22*S22*U22 -> 0.091734787 | W22: =VLOOKUP(D22,Priors!$A$3:$C$6,2,FALSE) -> 0.10751786 | X22: =VLOOKUP(D22,Priors!$A$3:$C$6,3,FALSE) -> 0.090240672 | Y22: =IF(N22="",W22,V22*N22+(1-V22)*W22) -> 0.10144286 | Z22: =IF(O22="",X22,V22*O22+(1-V22)*X22) -> 0.083856528 | AA22: 1 | AB22: 1 | AC22: =Y22*AA22 -> 0.10144286 | AD22: =Z22*AB22 -> 0.083856528 | AE22: =1-V22 -> 0.90826521 | AF22: PL history | AJ22: TRUE | AK22: FPL Core Insights / official FPL historical feed | AL22: https://github.com/olbauday/FPL-Core-Insights/tree/main/data/2025-2026 | AO22: 0 | AP22: FALSE | AQ22: Total xG retained; low penalty contamination
A23: 22 | B23: Nwaneri | C23: Arsenal | D23: MID | E23: Premier League | F23: Arsenal | G23: 165 | H23: 0.23 | I23: 0.08 | J23: 0.12545455 | K23: 0.043636364 | L23: 65.6 | M23: 1.7263158 | N23: 0.07267184 | O23: 0.025277162 | P23: =IFERROR(G23/(G23+Priors!$H$3),0) -> 0.1416309 | Q23: =IF(E23="Premier League",Priors!$H$4,IF(E23="Championship",Priors!$H$5,Priors!$H$8)) -> 1 | R23: FALSE | S23: =IF(R23=TRUE,Priors!$H$6,1) -> 1 | T23: FALSE | U23: =IF(T23=TRUE,Priors!$H$7,1) -> 1 | V23: =P23*Q23*S23*U23 -> 0.1416309 | W23: =VLOOKUP(D23,Priors!$A$3:$C$6,2,FALSE) -> 0.10751786 | X23: =VLOOKUP(D23,Priors!$A$3:$C$6,3,FALSE) -> 0.090240672 | Y23: =IF(N23="",W23,V23*N23+(1-V23)*W23) -> 0.10258259 | Z23: =IF(O23="",X23,V23*O23+(1-V23)*X23) -> 0.081039831 | AA23: 1 | AB23: 1 | AC23: =Y23*AA23 -> 0.10258259 | AD23: =Z23*AB23 -> 0.081039831 | AE23: =1-V23 -> 0.8583691 | AF23: PL history | AJ23: TRUE | AK23: FPL Core Insights / official FPL historical feed | AL23: https://github.com/olbauday/FPL-Core-Insights/tree/main/data/2025-2026 | AO23: 0 | AP23: FALSE | AQ23: Total xG retained; low penalty contamination
A24: 23 | B24: Fábio Vieira | C24: Arsenal | D24: MID | E24: Missing/non-PL | P24: =IFERROR(G24/(G24+Priors!$H$3),0) -> 0 | Q24: =IF(E24="Premier League",Priors!$H$4,IF(E24="Championship",Priors!$H$5,Priors!$H$8)) -> 0 | R24: FALSE | S24: =IF(R24=TRUE,Priors!$H$6,1) -> 1 | T24: FALSE | U24: =IF(T24=TRUE,Priors!$H$7,1) -> 1 | V24: =P24*Q24*S24*U24 -> 0 | W24: =VLOOKUP(D24,Priors!$A$3:$C$6,2,FALSE) -> 0.10751786 | X24: =VLOOKUP(D24,Priors!$A$3:$C$6,3,FALSE) -> 0.090240672 | Y24: =IF(N24="",W24,V24*N24+(1-V24)*W24) -> 0.10751786 | Z24: =IF(O24="",X24,V24*O24+(1-V24)*X24) -> 0.090240672 | AA24: 1 | AB24: 1 | AC24: =Y24*AA24 -> 0.10751786 | AD24: =Z24*AB24 -> 0.090240672 | AE24: =1-V24 -> 1 | AF24: Missing/non-PL | AJ24: TRUE | AK24: No reliable 25/26 history loaded | AO24: 0 | AP24: FALSE | AQ24: Total xG retained; low penalty contamination
A25: 24 | B25: Nelson | C25: Arsenal | D25: MID | E25: Premier League | F25: Brentford | G25: 118 | H25: 0.71 | I25: 0.11 | J25: 0.54152542 | K25: 0.083898305 | L25: 60.3 | M25: 1.5868421 | N25: 0.3412598 | O25: 0.052871237 | P25: =IFERROR(G25/(G25+Priors!$H$3),0) -> 0.10554562 | Q25: =IF(E25="Premier League",Priors!$H$4,IF(E25="Championship",Priors!$H$5,Priors!$H$8)) -> 1 | R25: TRUE | S25: =IF(R25=TRUE,Priors!$H$6,1) -> 0.85 | T25: FALSE | U25: =IF(T25=TRUE,Priors!$H$7,1) -> 1 | V25: =P25*Q25*S25*U25 -> 0.089713775 | W25: =VLOOKUP(D25,Priors!$A$3:$C$6,2,FALSE) -> 0.10751786 | X25: =VLOOKUP(D25,Priors!$A$3:$C$6,3,FALSE) -> 0.090240672 | Y25: =IF(N25="",W25,V25*N25+(1-V25)*W25) -> 0.12848773 | Z25: =IF(O25="",X25,V25*O25+(1-V25)*X25) -> 0.086888119 | AA25: 1 | AB25: 1 | AC25: =Y25*AA25 -> 0.12848773 | AD25: =Z25*AB25 -> 0.086888119 | AE25: =1-V25 -> 0.91028623 | AF25: PL history | AJ25: TRUE | AK25: FPL Core Insights / official FPL historical feed | AL25: https://github.com/olbauday/FPL-Core-Insights/tree/main/data/2025-2026 | AO25: 0 | AP25: FALSE | AQ25: Total xG retained; low penalty contamination
A26: 25 | B26: Gyökeres | C26: Arsenal | D26: FWD | E26: Premier League | F26: Arsenal | G26: 2217 | H26: 12.26 | I26: 1.94 | J26: 0.49769959 | K26: 0.078755074 | L26: 65.6 | M26: 1.7263158 | N26: 0.28830159 | O26: 0.045620318 | P26: =IFERROR(G26/(G26+Priors!$H$3),0) -> 0.68915138 | Q26: =IF(E26="Premier League",Priors!$H$4,IF(E26="Championship",Priors!$H$5,Priors!$H$8)) -> 1 | R26: FALSE | S26: =IF(R26=TRUE,Priors!$H$6,1) -> 1 | T26: FALSE | U26: =IF(T26=TRUE,Priors!$H$7,1) -> 1 | V26: =P26*Q26*S26*U26 -> 0.68915138 | W26: =VLOOKUP(D26,Priors!$A$3:$C$6,2,FALSE) -> 0.30461526 | X26: =VLOOKUP(D26,Priors!$A$3:$C$6,3,FALSE) -> 0.039258062 | Y26: =IF(N26="",W26,V26*N26+(1-V26)*W26) -> 0.29337267 | Z26: =IF(O26="",X26,V26*O26+(1-V26)*X26) -> 0.043642619 | AA26: 1 | AB26: 1 | AC26: =Y26*AA26 -> 0.29337267 | AD26: =Z26*AB26 -> 0.043642619 | AE26: =1-V26 -> 0.31084862 | AF26: PL history | AG26: 2 | AJ26: FALSE | AK26: FPL Core Insights / official FPL historical feed | AL26: https://github.com/olbauday/FPL-Core-Insights/tree/main/data/2025-2026 | AN26: 2 | AO26: 0 | AP26: TRUE | AQ26: Total xG retained; penalty channel not decomposed
A27: 26 | B27: Havertz | C27: Arsenal | D27: FWD | E27: Premier League | F27: Arsenal | G27: 577 | H27: 3.31 | I27: 0.64 | J27: 0.51629116 | K27: 0.09982669 | L27: 65.6 | M27: 1.7263158 | N27: 0.2990711 | O27: 0.057826436 | P27: =IFERROR(G27/(G27+Priors!$H$3),0) -> 0.36588459 | Q27: =IF(E27="Premier League",Priors!$H$4,IF(E27="Championship",Priors!$H$5,Priors!$H$8)) -> 1 | R27: FALSE | S27: =IF(R27=TRUE,Priors!$H$6,1) -> 1 | T27: FALSE | U27: =IF(T27=TRUE,Priors!$H$7,1) -> 1 | V27: =P27*Q27*S27*U27 -> 0.36588459 | W27: =VLOOKUP(D27,Priors!$A$3:$C$6,2,FALSE) -> 0.30461526 | X27: =VLOOKUP(D27,Priors!$A$3:$C$6,3,FALSE) -> 0.039258062 | Y27: =IF(N27="",W27,V27*N27+(1-V27)*W27) -> 0.30258673 | Z27: =IF(O27="",X27,V27*O27+(1-V27)*X27) -> 0.046051944 | AA27: 1 | AB27: 1 | AC27: =Y27*AA27 -> 0.30258673 | AD27: =Z27*AB27 -> 0.046051944 | AE27: =1-V27 -> 0.63411541 | AF27: PL history | AJ27: TRUE | AK27: FPL Core Insights / official FPL historical feed | AL27: https://github.com/olbauday/FPL-Core-Insights/tree/main/data/2025-2026 | AO27: 0 | AP27: FALSE | AQ27: Total xG retained; low penalty contamination
A28: 27 | B28: G.Jesus | C28: Arsenal | D28: FWD | E28: Premier League | F28: Arsenal | G28: 418 | H28: 2.71 | I28: 0.26 | J28: 0.58349282 | K28: 0.055980861 | L28: 65.6 | M28: 1.7263158 | N28: 0.33799889 | O28: 0.032427938 | P28: =IFERROR(G28/(G28+Priors!$H$3),0) -> 0.29478138 | Q28: =IF(E28="Premier League",Priors!$H$4,IF(E28="Championship",Priors!$H$5,Priors!$H$8)) -> 1 | R28: FALSE | S28: =IF(R28=TRUE,Priors!$H$6,1) -> 1 | T28: FALSE | U28: =IF(T28=TRUE,Priors!$H$7,1) -> 1 | V28: =P28*Q28*S28*U28 -> 0.29478138 | W28: =VLOOKUP(D28,Priors!$A$3:$C$6,2,FALSE) -> 0.30461526 | X28: =VLOOKUP(D28,Priors!$A$3:$C$6,3,FALSE) -> 0.039258062 | Y28: =IF(N28="",W28,V28*N28+(1-V28)*W28) -> 0.31445613 | Z28: =IF(O28="",X28,V28*O28+(1-V28)*X28) -> 0.037244668 | AA28: 1 | AB28: 1 | AC28: =Y28*AA28 -> 0.31445613 | AD28: =Z28*AB28 -> 0.037244668 | AE28: =1-V28 -> 0.70521862 | AF28: PL history | AJ28: TRUE | AK28: FPL Core Insights / official FPL historical feed | AL28: https://github.com/olbauday/FPL-Core-Insights/tree/main/data/2025-2026 | AO28: 0 | AP28: FALSE | AQ28: Total xG retained; low penalty contamination
A29: 557 | B29: Tzolis | C29: Arsenal | D29: MID | E29: Missing/non-PL | P29: =IFERROR(G29/(G29+Priors!$H$3),0) -> 0 | Q29: =IF(E29="Premier League",Priors!$H$4,IF(E29="Championship",Priors!$H$5,Priors!$H$8)) -> 0 | R29: FALSE | S29: =IF(R29=TRUE,Priors!$H$6,1) -> 1 | T29: FALSE | U29: =IF(T29=TRUE,Priors!$H$7,1) -> 1 | V29: =P29*Q29*S29*U29 -> 0 | W29: =VLOOKUP(D29,Priors!$A$3:$C$6,2,FALSE) -> 0.10751786 | X29: =VLOOKUP(D29,Priors!$A$3:$C$6,3,FALSE) -> 0.090240672 | Y29: =IF(N29="",W29,V29*N29+(1-V29)*W29) -> 0.10751786 | Z29: =IF(O29="",X29,V29*O29+(1-V29)*X29) -> 0.090240672 | AA29: 1 | AB29: 1 | AC29: =Y29*AA29 -> 0.10751786 | AD29: =Z29*AB29 -> 0.090240672 | AE29: =1-V29 -> 1 | AF29: Missing/non-PL | AJ29: TRUE | AK29: No reliable 25/26 history loaded | AO29: 0 | AP29: FALSE | AQ29: Total xG retained; low penalty contamination
A30: 28 | B30: Martinez | C30: Aston Villa | D30: GK | E30: Premier League | F30: Aston Villa | G30: 2835 | H30: 0 | I30: 0.08 | J30: 0 | K30: 0.0025396825 | L30: 48.2 | M30: 1.2684211 | N30: 0 | O30: 0.0020022393 | P30: =IFERROR(G30/(G30+Priors!$H$3),0) -> 0.73924381 | Q30: =IF(E30="Premier League",Priors!$H$4,IF(E30="Championship",Priors!$H$5,Priors!$H$8)) -> 1 | R30: FALSE | S30: =IF(R30=TRUE,Priors!$H$6,1) -> 1 | T30: FALSE | U30: =IF(T30=TRUE,Priors!$H$7,1) -> 1 | V30: =P30*Q30*S30*U30 -> 0.73924381 | W30: =VLOOKUP(D30,Priors!$A$3:$C$6,2,FALSE) -> 0.00016719535 | X30: =VLOOKUP(D30,Priors!$A$3:$C$6,3,FALSE) -> 0.0013793616 | Y30: =IF(N30="",W30,V30*N30+(1-V30)*W30) -> 4.3597223e-05 | Z30: =IF(O30="",X30,V30*O30+(1-V30)*X30) -> 0.0018398201 | AA30: 1 | AB30: 1 | AC30: =Y30*AA30 -> 4.3597223e-05 | AD30: =Z30*AB30 -> 0.0018398201 | AE30: =1-V30 -> 0.26075619 | AF30: PL history | AJ30: FALSE | AK30: FPL Core Insights / official FPL historical feed | AL30: https://github.com/olbauday/FPL-Core-Insights/tree/main/data/2025-2026 | AO30: 0 | AP30: FALSE | AQ30: Total xG retained; low penalty contamination
A31: 29 | B31: M.Bizot | C31: Aston Villa | D31: GK | E31: Premier League | F31: Aston Villa | G31: 585 | H31: 0 | I31: 0 | J31: 0 | K31: 0 | L31: 48.2 | M31: 1.2684211 | N31: 0 | O31: 0 | P31: =IFERROR(G31/(G31+Priors!$H$3),0) -> 0.36908517 | Q31: =IF(E31="Premier League",Priors!$H$4,IF(E31="Championship",Priors!$H$5,Priors!$H$8)) -> 1 | R31: FALSE | S31: =IF(R31=TRUE,Priors!$H$6,1) -> 1 | T31: FALSE | U31: =IF(T31=TRUE,Priors!$H$7,1) -> 1 | V31: =P31*Q31*S31*U31 -> 0.36908517 | W31: =VLOOKUP(D31,Priors!$A$3:$C$6,2,FALSE) -> 0.00016719535 | X31: =VLOOKUP(D31,Priors!$A$3:$C$6,3,FALSE) -> 0.0013793616 | Y31: =IF(N31="",W31,V31*N31+(1-V31)*W31) -> 0.00010548603 | Z31: =IF(O31="",X31,V31*O31+(1-V31)*X31) -> 0.00087025971 | AA31: 1 | AB31: 1 | AC31: =Y31*AA31 -> 0.00010548603 | AD31: =Z31*AB31 -> 0.00087025971 | AE31: =1-V31 -> 0.63091483 | AF31: PL history | AJ31: TRUE | AK31: FPL Core Insights / official FPL historical feed | AL31: https://github.com/olbauday/FPL-Core-Insights/tree/main/data/2025-2026 | AO31: 0 | AP31: FALSE | AQ31: Total xG retained; low penalty contamination
A32: 30 | B32: Digne | C32: Aston Villa | D32: DEF | E32: Premier League | F32: Aston Villa | G32: 1842 | H32: 0.67 | I32: 3.28 | J32: 0.032736156 | K32: 0.16026059 | L32: 48.2 | M32: 1.2684211 | N32: 0.025808588 | O32: 0.12634652 | P32: =IFERROR(G32/(G32+Priors!$H$3),0) -> 0.64813512 | Q32: =IF(E32="Premier League",Priors!$H$4,IF(E32="Championship",Priors!$H$5,Priors!$H$8)) -> 1 | R32: FALSE | S32: =IF(R32=TRUE,Priors!$H$6,1) -> 1 | T32: FALSE | U32: =IF(T32=TRUE,Priors!$H$7,1) -> 1 | V32: =P32*Q32*S32*U32 -> 0.64813512 | W32: =VLOOKUP(D32,Priors!$A$3:$C$6,2,FALSE) -> 0.041142361 | X32: =VLOOKUP(D32,Priors!$A$3:$C$6,3,FALSE) -> 0.04051308 | Y32: =IF(N32="",W32,V32*N32+(1-V32)*W32) -> 0.031204004 | Z32: =IF(O32="",X32,V32*O32+(1-V32)*X32) -> 0.096144747 | AA32: 1 | AB32: 1 | AC32: =Y32*AA32 -> 0.031204004 | AD32: =Z32*AB32 -> 0.096144747 | AE32: =1-V32 -> 0.35186488 | AF32: PL history | AI32: 4 | AJ32: FALSE | AK32: FPL Core Insights / official FPL historical feed | AL32: https://github.com/olbauday/FPL-Core-Insights/tree/main/data/2025-2026 | AO32: 0 | AP32: FALSE | AQ32: Total xG retained; low penalty contamination
A33: 31 | B33: Konsa | C33: Aston Villa | D33: DEF | E33: Premier League | F33: Aston Villa | G33: 3035 | H33: 1.27 | I33: 0.59 | J33: 0.037660626 | K33: 0.017495881 | L33: 48.2 | M33: 1.2684211 | N33: 0.02969095 | O33: 0.013793433 | P33: =IFERROR(G33/(G33+Priors!$H$3),0) -> 0.75216853 | Q33: =IF(E33="Premier League",Priors!$H$4,IF(E33="Championship",Priors!$H$5,Priors!$H$8)) -> 1 | R33: FALSE | S33: =IF(R33=TRUE,Priors!$H$6,1) -> 1 | T33: FALSE | U33: =IF(T33=TRUE,Priors!$H$7,1) -> 1 | V33: =P33*Q33*S33*U33 -> 0.75216853 | W33: =VLOOKUP(D33,Priors!$A$3:$C$6,2,FALSE) -> 0.041142361 | X33: =VLOOKUP(D33,Priors!$A$3:$C$6,3,FALSE) -> 0.04051308 | Y33: =IF(N33="",W33,V33*N33+(1-V33)*W33) -> 0.03252897 | Z33: =IF(O33="",X33,V33*O33+(1-V33)*X33) -> 0.020415403 | AA33: 1 | AB33: 1 | AC33: =Y33*AA33 -> 0.03252897 | AD33: =Z33*AB33 -> 0.020415403 | AE33: =1-V33 -> 0.24783147 | AF33: PL history | AJ33: FALSE | AK33: FPL Core Insights / official FPL historical feed | AL33: https://github.com/olbauday/FPL-Core-Insights/tree/main/data/2025-2026 | AO33: 0 | AP33: FALSE | AQ33: Total xG retained; low penalty contamination
A34: 32 | B34: Cash | C34: Aston Villa | D34: DEF | E34: Premier League | F34: Aston Villa | G34: 3016 | H34: 1.14 | I34: 2.94 | J34: 0.034018568 | K34: 0.087732095 | L34: 48.2 | M34: 1.2684211 | N34: 0.026819618 | O34: 0.069166382 | P34: =IFERROR(G34/(G34+Priors!$H$3),0) -> 0.75099602 | Q34: =IF(E34="Premier League",Priors!$H$4,IF(E34="Championship",Priors!$H$5,Priors!$H$8)) -> 1 | R34: FALSE | S34: =IF(R34=TRUE,Priors!$H$6,1) -> 1 | T34: FALSE | U34: =IF(T34=TRUE,Priors!$H$7,1) -> 1 | V34: =P34*Q34*S34*U34 -> 0.75099602 | W34: =VLOOKUP(D34,Priors!$A$3:$C$6,2,FALSE) -> 0.041142361 | X34: =VLOOKUP(D34,Priors!$A$3:$C$6,3,FALSE) -> 0.04051308 | Y34: =IF(N34="",W34,V34*N34+(1-V34)*W34) -> 0.030386038 | Z34: =IF(O34="",X34,V34*O34+(1-V34)*X34) -> 0.062031596 | AA34: 1 | AB34: 1 | AC34: =Y34*AA34 -> 0.030386038 | AD34: =Z34*AB34 -> 0.062031596 | AE34: =1-V34 -> 0.24900398 | AF34: PL history | AI34: 5 | AJ34: FALSE | AK34: FPL Core Insights / official FPL historical feed | AL34: https://github.com/olbauday/FPL-Core-Insights/tree/main/data/2025-2026 | AO34: 0 | AP34: FALSE | AQ34: Total xG retained; low penalty contamination
A35: 33 | B35: Mings | C35: Aston Villa | D35: DEF | E35: Premier League | F35: Aston Villa | G35: 1322 | H35: 1.3 | I35: 0.42 | J35: 0.088502269 | K35: 0.028593041 | L35: 48.2 | M35: 1.2684211 | N35: 0.069773573 | O35: 0.022542231 | P35: =IFERROR(G35/(G35+Priors!$H$3),0) -> 0.56933678 | Q35: =IF(E35="Premier League",Priors!$H$4,IF(E35="Championship",Priors!$H$5,Priors!$H$8)) -> 1 | R35: FALSE | S35: =IF(R35=TRUE,Priors!$H$6,1) -> 1 | T35: FALSE | U35: =IF(T35=TRUE,Priors!$H$7,1) -> 1 | V35: =P35*Q35*S35*U35 -> 0.56933678 | W35: =VLOOKUP(D35,Priors!$A$3:$C$6,2,FALSE) -> 0.041142361 | X35: =VLOOKUP(D35,Priors!$A$3:$C$6,3,FALSE) -> 0.04051308 | Y35: =IF(N35="",W35,V35*N35+(1-V35)*W35) -> 0.057443163 | Z35: =IF(O35="",X35,V35*O35+(1-V35)*X35) -> 0.030281615 | AA35: 1 | AB35: 1 | AC35: =Y35*AA35 -> 0.057443163 | AD35: =Z35*AB35 -> 0.030281615 | AE35: =1-V35 -> 0.43066322 | AF35: PL history | AJ35: FALSE | AK35: FPL Core Insights / official FPL historical feed | AL35: https://github.com/olbauday/FPL-Core-Insights/tree/main/data/2025-2026 | AO35: 0 | AP35: FALSE | AQ35: Total xG retained; low penalty contamination
A36: 34 | B36: Pau | C36: Aston Villa | D36: DEF | E36: Premier League | F36: Aston Villa | G36: 1673 | H36: 1.33 | I36: 0.39 | J36: 0.071548117 | K36: 0.020980275 | L36: 48.2 | M36: 1.2684211 | N36: 0.056407229 | O36: 0.016540466 | P36: =IFERROR(G36/(G36+Priors!$H$3),0) -> 0.62588851 | Q36: =IF(E36="Premier League",Priors!$H$4,IF(E36="Championship",Priors!$H$5,Priors!$H$8)) -> 1 | R36: FALSE | S36: =IF(R36=TRUE,Priors!$H$6,1) -> 1 | T36: FALSE | U36: =IF(T36=TRUE,Priors!$H$7,1) -> 1 | V36: =P36*Q36*S36*U36 -> 0.62588851 | W36: =VLOOKUP(D36,Priors!$A$3:$C$6,2,FALSE) -> 0.041142361 | X36: =VLOOKUP(D36,Priors!$A$3:$C$6,3,FALSE) -> 0.04051308 | Y36: =IF(N36="",W36,V36*N36+(1-V36)*W36) -> 0.050696467 | Z36: =IF(O36="",X36,V36*O36+(1-V36)*X36) -> 0.025508896 | AA36: 1 | AB36: 1 | AC36: =Y36*AA36 -> 0.050696467 | AD36: =Z36*AB36 -> 0.025508896 | AE36: =1-V36 -> 0.37411149 | AF36: PL history | AJ36: FALSE | AK36: FPL Core Insights / official FPL historical feed | AL36: https://github.com/olbauday/FPL-Core-Insights/tree/main/data/2025-2026 | AO36: 0 | AP36: FALSE | AQ36: Total xG retained; low penalty contamination
A37: 35 | B37: Bogarde | C37: Aston Villa | D37: MID | E37: Premier League | F37: Aston Villa | G37: 1042 | H37: 0 | I37: 0.2 | J37: 0 | K37: 0.017274472 | L37: 48.2 | M37: 1.2684211 | N37: 0 | O37: 0.013618878 | P37: =IFERROR(G37/(G37+Priors!$H$3),0) -> 0.51028404 | Q37: =IF(E37="Premier League",Priors!$H$4,IF(E37="Championship",Priors!$H$5,Priors!$H$8)) -> 1 | R37: FALSE | S37: =IF(R37=TRUE,Priors!$H$6,1) -> 1 | T37: FALSE | U37: =IF(T37=TRUE,Priors!$H$7,1) -> 1 | V37: =P37*Q37*S37*U37 -> 0.51028404 | W37: =VLOOKUP(D37,Priors!$A$3:$C$6,2,FALSE) -> 0.10751786 | X37: =VLOOKUP(D37,Priors!$A$3:$C$6,3,FALSE) -> 0.090240672 | Y37: =IF(N37="",W37,V37*N37+(1-V37)*W37) -> 0.052653213 | Z37: =IF(O37="",X37,V37*O37+(1-V37)*X37) -> 0.051141794 | AA37: 1 | AB37: 1 | AC37: =Y37*AA37 -> 0.052653213 | AD37: =Z37*AB37 -> 0.051141794 | AE37: =1-V37 -> 0.48971596 | AF37: PL history | AJ37: FALSE | AK37: FPL Core Insights / official FPL historical feed | AL37: https://github.com/olbauday/FPL-Core-Insights/tree/main/data/2025-2026 | AO37: 0 | AP37: FALSE | AQ37: Total xG retained; low penalty contamination
A38: 36 | B38: Maatsen | C38: Aston Villa | D38: DEF | E38: Premier League | F38: Aston Villa | G38: 1590 | H38: 1.26 | I38: 2.39 | J38: 0.071320755 | K38: 0.13528302 | L38: 48.2 | M38: 1.2684211 | N38: 0.056227981 | O38: 0.10665466 | P38: =IFERROR(G38/(G38+Priors!$H$3),0) -> 0.61389961 | Q38: =IF(E38="Premier League",Priors!$H$4,IF(E38="Championship",Priors!$H$5,Priors!$H$8)) -> 1 | R38: FALSE | S38: =IF(R38=TRUE,Priors!$H$6,1) -> 1 | T38: FALSE | U38: =IF(T38=TRUE,Priors!$H$7,1) -> 1 | V38: =P38*Q38*S38*U38 -> 0.61389961 | W38: =VLOOKUP(D38,Priors!$A$3:$C$6,2,FALSE) -> 0.041142361 | X38: =VLOOKUP(D38,Priors!$A$3:$C$6,3,FALSE) -> 0.04051308 | Y38: =IF(N38="",W38,V38*N38+(1-V38)*W38) -> 0.050403417 | Z38: =IF(O38="",X38,V38*O38+(1-V38)*X38) -> 0.081117372 | AA38: 1 | AB38: 1 | AC38: =Y38*AA38 -> 0.050403417 | AD38: =Z38*AB38 -> 0.081117372 | AE38: =1-V38 -> 0.38610039 | AF38: PL history | AJ38: FALSE | AK38: FPL Core Insights / official FPL historical feed | AL38: https://github.com/olbauday/FPL-Core-Insights/tree/main/data/2025-2026 | AO38: 0 | AP38: FALSE | AQ38: Total xG retained; low penalty contamination
